[2025-10-04 13:19:52,106][flwr][DEBUG] - Pre-registering run with id 7134596778794444889
[2025-10-04 13:19:52,108][flwr][DEBUG] - Using InMemoryState
[2025-10-04 13:19:52,108][flwr][DEBUG] - Using InMemoryState
[2025-10-04 13:19:52,108][flwr][DEBUG] - Using InMemoryState
[2025-10-04 13:19:52,110][flwr][DEBUG] - Registered 3 nodes
[2025-10-04 13:19:52,110][flwr][DEBUG] - Supported backends: ['ray']
[2025-10-04 13:19:52,115][flwr][DEBUG] - Initialising: RayBackend
[2025-10-04 13:19:52,117][flwr][DEBUG] - Backend config: {'num_cpus': 2, 'num_gpus': 0.0, 'init_args': {'logging_level': 30, 'log_to_driver': True}, 'client_resources': {'num_cpus': 2, 'num_gpus': 0}, 'actor': {'tensorflow': 0}}
[2025-10-04 13:19:52,433][flwr][INFO] - Starting Flower ServerApp, config: num_rounds=3, no round_timeout
[2025-10-04 13:19:52,435][flwr][INFO] - 
[2025-10-04 13:19:52,436][flwr][INFO] - [INIT]
[2025-10-04 13:19:52,436][flwr][INFO] - Requesting initial parameters from one random client
[2025-10-04 13:20:09,747][flwr][DEBUG] - Constructed ActorPool with: 1 actors
[2025-10-04 13:20:09,749][flwr][DEBUG] - Using InMemoryState
[2025-10-04 13:20:31,057][flwr][INFO] - Received initial parameters from one random client
[2025-10-04 13:20:31,057][flwr][INFO] - Starting evaluation of initial global parameters
[2025-10-04 13:20:31,057][flwr][INFO] - Evaluation returned no results (`None`)
[2025-10-04 13:20:31,057][flwr][INFO] - 
[2025-10-04 13:20:31,057][flwr][INFO] - [ROUND 1]
[2025-10-04 13:20:31,058][flwr][INFO] - configure_fit: strategy sampled 3 clients (out of 3)
[2025-10-04 13:20:32,102][flwr][ERROR] - An exception was raised when processing a message by RayBackend
[2025-10-04 13:20:32,102][flwr][ERROR] - [36mray::ClientAppActor.run()[39m (pid=34043, ip=172.28.0.12, actor_id=68fd605311493b9d27ffc31c01000000, repr=<flwr.simulation.ray_transport.ray_actor.ClientAppActor object at 0x7bee5686ae10>)
                  ^^^^^^^^^^^^^^^^^^^^^^^^^^^^^^^^^^^^^
  File "/usr/local/lib/python3.12/dist-packages/flwr/client/client_app.py", line 144, in __call__
    return self._call(message, context)
           ^^^^^^^^^^^^^^^^^^^^^^^^^^^^
  File "/usr/local/lib/python3.12/dist-packages/flwr/client/client_app.py", line 128, in ffn
    out_message = handle_legacy_message_from_msgtype(
                  ^^^^^^^^^^^^^^^^^^^^^^^^^^^^^^^^^^^
  File "/usr/local/lib/python3.12/dist-packages/flwr/client/message_handler/message_handler.py", line 128, in handle_legacy_message_from_msgtype
    fit_res = maybe_call_fit(
              ^^^^^^^^^^^^^^^
  File "/usr/local/lib/python3.12/dist-packages/flwr/client/client.py", line 224, in maybe_call_fit
    return client.fit(fit_ins)
           ^^^^^^^^^^^^^^^^^^^
  File "/usr/local/lib/python3.12/dist-packages/flwr/client/numpy_client.py", line 227, in _fit
    results = self.numpy_client.fit(parameters, ins.config)  # type: ignore
              ^^^^^^^^^^^^^^^^^^^^^^^^^^^^^^^^^^^^^^^^^^^^^
TypeError: FederatedClient.fit() takes 2 positional arguments but 3 were given

The above exception was the direct cause of the following exception:

[36mray::ClientAppActor.run()[39m (pid=34043, ip=172.28.0.12, actor_id=68fd605311493b9d27ffc31c01000000, repr=<flwr.simulation.ray_transport.ray_actor.ClientAppActor object at 0x7bee5686ae10>)
           ^^^^^^^^^^^^^^^^^^^^^^^^^^^^^^^^^^^^
           ^^^^^^^^^^^^^^^^^^^^^^^^^^^^^^^
  File "/usr/local/lib/python3.12/dist-packages/flwr/simulation/ray_transport/ray_actor.py", line 64, in run
    raise ClientAppException(str(ex)) from ex
flwr.client.client_app.ClientAppException: 
Exception ClientAppException occurred. Message: FederatedClient.fit() takes 2 positional arguments but 3 were given
[2025-10-04 13:20:32,105][flwr][ERROR] - Traceback (most recent call last):
  File "/usr/local/lib/python3.12/dist-packages/flwr/server/superlink/fleet/vce/vce_api.py", line 111, in worker
    out_mssg, updated_context = backend.process_message(message, context)
                                ^^^^^^^^^^^^^^^^^^^^^^^^^^^^^^^^^^^^^^^^^
  File "/usr/local/lib/python3.12/dist-packages/flwr/server/superlink/fleet/vce/backend/raybackend.py", line 189, in process_message
    raise ex
  File "/usr/local/lib/python3.12/dist-packages/flwr/server/superlink/fleet/vce/backend/raybackend.py", line 176, in process_message
    ) = self.pool.fetch_result_and_return_actor_to_pool(future)
        ^^^^^^^^^^^^^^^^^^^^^^^^^^^^^^^^^^^^^^^^^^^^^^^^^^^^^^^
  File "/usr/local/lib/python3.12/dist-packages/flwr/simulation/ray_transport/ray_actor.py", line 480, in fetch_result_and_return_actor_to_pool
    _, out_mssg, updated_context = ray.get(future)
                                   ^^^^^^^^^^^^^^^
  File "/usr/local/lib/python3.12/dist-packages/ray/_private/auto_init_hook.py", line 21, in auto_init_wrapper
    return fn(*args, **kwargs)
           ^^^^^^^^^^^^^^^^^^^
  File "/usr/local/lib/python3.12/dist-packages/ray/_private/client_mode_hook.py", line 103, in wrapper
    return func(*args, **kwargs)
           ^^^^^^^^^^^^^^^^^^^^^
  File "/usr/local/lib/python3.12/dist-packages/ray/_private/worker.py", line 2639, in get
    values, debugger_breakpoint = worker.get_objects(object_refs, timeout=timeout)
                                  ^^^^^^^^^^^^^^^^^^^^^^^^^^^^^^^^^^^^^^^^^^^^^^^^
  File "/usr/local/lib/python3.12/dist-packages/ray/_private/worker.py", line 864, in get_objects
    raise value.as_instanceof_cause()
ray.exceptions.RayTaskError(ClientAppException): [36mray::ClientAppActor.run()[39m (pid=34043, ip=172.28.0.12, actor_id=68fd605311493b9d27ffc31c01000000, repr=<flwr.simulation.ray_transport.ray_actor.ClientAppActor object at 0x7bee5686ae10>)
                  ^^^^^^^^^^^^^^^^^^^^^^^^^^^^^^^^^^^^^
  File "/usr/local/lib/python3.12/dist-packages/flwr/client/client_app.py", line 144, in __call__
    return self._call(message, context)
           ^^^^^^^^^^^^^^^^^^^^^^^^^^^^
  File "/usr/local/lib/python3.12/dist-packages/flwr/client/client_app.py", line 128, in ffn
    out_message = handle_legacy_message_from_msgtype(
                  ^^^^^^^^^^^^^^^^^^^^^^^^^^^^^^^^^^^
  File "/usr/local/lib/python3.12/dist-packages/flwr/client/message_handler/message_handler.py", line 128, in handle_legacy_message_from_msgtype
    fit_res = maybe_call_fit(
              ^^^^^^^^^^^^^^^
  File "/usr/local/lib/python3.12/dist-packages/flwr/client/client.py", line 224, in maybe_call_fit
    return client.fit(fit_ins)
           ^^^^^^^^^^^^^^^^^^^
  File "/usr/local/lib/python3.12/dist-packages/flwr/client/numpy_client.py", line 227, in _fit
    results = self.numpy_client.fit(parameters, ins.config)  # type: ignore
              ^^^^^^^^^^^^^^^^^^^^^^^^^^^^^^^^^^^^^^^^^^^^^
TypeError: FederatedClient.fit() takes 2 positional arguments but 3 were given

The above exception was the direct cause of the following exception:

[36mray::ClientAppActor.run()[39m (pid=34043, ip=172.28.0.12, actor_id=68fd605311493b9d27ffc31c01000000, repr=<flwr.simulation.ray_transport.ray_actor.ClientAppActor object at 0x7bee5686ae10>)
           ^^^^^^^^^^^^^^^^^^^^^^^^^^^^^^^^^^^^
           ^^^^^^^^^^^^^^^^^^^^^^^^^^^^^^^
  File "/usr/local/lib/python3.12/dist-packages/flwr/simulation/ray_transport/ray_actor.py", line 64, in run
    raise ClientAppException(str(ex)) from ex
flwr.client.client_app.ClientAppException: 
Exception ClientAppException occurred. Message: FederatedClient.fit() takes 2 positional arguments but 3 were given

[2025-10-04 13:20:32,707][flwr][ERROR] - An exception was raised when processing a message by RayBackend
[2025-10-04 13:20:32,708][flwr][ERROR] - [36mray::ClientAppActor.run()[39m (pid=34043, ip=172.28.0.12, actor_id=68fd605311493b9d27ffc31c01000000, repr=<flwr.simulation.ray_transport.ray_actor.ClientAppActor object at 0x7bee5686ae10>)
                  ^^^^^^^^^^^^^^^^^^^^^^^^^^^^^^^^^^^^^
  File "/usr/local/lib/python3.12/dist-packages/flwr/client/client_app.py", line 144, in __call__
    return self._call(message, context)
           ^^^^^^^^^^^^^^^^^^^^^^^^^^^^
  File "/usr/local/lib/python3.12/dist-packages/flwr/client/client_app.py", line 128, in ffn
    out_message = handle_legacy_message_from_msgtype(
                  ^^^^^^^^^^^^^^^^^^^^^^^^^^^^^^^^^^^
  File "/usr/local/lib/python3.12/dist-packages/flwr/client/message_handler/message_handler.py", line 128, in handle_legacy_message_from_msgtype
    fit_res = maybe_call_fit(
              ^^^^^^^^^^^^^^^
  File "/usr/local/lib/python3.12/dist-packages/flwr/client/client.py", line 224, in maybe_call_fit
    return client.fit(fit_ins)
           ^^^^^^^^^^^^^^^^^^^
  File "/usr/local/lib/python3.12/dist-packages/flwr/client/numpy_client.py", line 227, in _fit
    results = self.numpy_client.fit(parameters, ins.config)  # type: ignore
              ^^^^^^^^^^^^^^^^^^^^^^^^^^^^^^^^^^^^^^^^^^^^^
TypeError: FederatedClient.fit() takes 2 positional arguments but 3 were given

The above exception was the direct cause of the following exception:

[36mray::ClientAppActor.run()[39m (pid=34043, ip=172.28.0.12, actor_id=68fd605311493b9d27ffc31c01000000, repr=<flwr.simulation.ray_transport.ray_actor.ClientAppActor object at 0x7bee5686ae10>)
           ^^^^^^^^^^^^^^^^^^^^^^^^^^^^^^^^^^^^
           ^^^^^^^^^^^^^^^^^^^^^^^^^^^^^^^
  File "/usr/local/lib/python3.12/dist-packages/flwr/simulation/ray_transport/ray_actor.py", line 64, in run
    raise ClientAppException(str(ex)) from ex
flwr.client.client_app.ClientAppException: 
Exception ClientAppException occurred. Message: FederatedClient.fit() takes 2 positional arguments but 3 were given
[2025-10-04 13:20:32,709][flwr][ERROR] - Traceback (most recent call last):
  File "/usr/local/lib/python3.12/dist-packages/flwr/server/superlink/fleet/vce/vce_api.py", line 111, in worker
    out_mssg, updated_context = backend.process_message(message, context)
                                ^^^^^^^^^^^^^^^^^^^^^^^^^^^^^^^^^^^^^^^^^
  File "/usr/local/lib/python3.12/dist-packages/flwr/server/superlink/fleet/vce/backend/raybackend.py", line 189, in process_message
    raise ex
  File "/usr/local/lib/python3.12/dist-packages/flwr/server/superlink/fleet/vce/backend/raybackend.py", line 176, in process_message
    ) = self.pool.fetch_result_and_return_actor_to_pool(future)
        ^^^^^^^^^^^^^^^^^^^^^^^^^^^^^^^^^^^^^^^^^^^^^^^^^^^^^^^
  File "/usr/local/lib/python3.12/dist-packages/flwr/simulation/ray_transport/ray_actor.py", line 480, in fetch_result_and_return_actor_to_pool
    _, out_mssg, updated_context = ray.get(future)
                                   ^^^^^^^^^^^^^^^
  File "/usr/local/lib/python3.12/dist-packages/ray/_private/auto_init_hook.py", line 21, in auto_init_wrapper
    return fn(*args, **kwargs)
           ^^^^^^^^^^^^^^^^^^^
  File "/usr/local/lib/python3.12/dist-packages/ray/_private/client_mode_hook.py", line 103, in wrapper
    return func(*args, **kwargs)
           ^^^^^^^^^^^^^^^^^^^^^
  File "/usr/local/lib/python3.12/dist-packages/ray/_private/worker.py", line 2639, in get
    values, debugger_breakpoint = worker.get_objects(object_refs, timeout=timeout)
                                  ^^^^^^^^^^^^^^^^^^^^^^^^^^^^^^^^^^^^^^^^^^^^^^^^
  File "/usr/local/lib/python3.12/dist-packages/ray/_private/worker.py", line 864, in get_objects
    raise value.as_instanceof_cause()
ray.exceptions.RayTaskError(ClientAppException): [36mray::ClientAppActor.run()[39m (pid=34043, ip=172.28.0.12, actor_id=68fd605311493b9d27ffc31c01000000, repr=<flwr.simulation.ray_transport.ray_actor.ClientAppActor object at 0x7bee5686ae10>)
                  ^^^^^^^^^^^^^^^^^^^^^^^^^^^^^^^^^^^^^
  File "/usr/local/lib/python3.12/dist-packages/flwr/client/client_app.py", line 144, in __call__
    return self._call(message, context)
           ^^^^^^^^^^^^^^^^^^^^^^^^^^^^
  File "/usr/local/lib/python3.12/dist-packages/flwr/client/client_app.py", line 128, in ffn
    out_message = handle_legacy_message_from_msgtype(
                  ^^^^^^^^^^^^^^^^^^^^^^^^^^^^^^^^^^^
  File "/usr/local/lib/python3.12/dist-packages/flwr/client/message_handler/message_handler.py", line 128, in handle_legacy_message_from_msgtype
    fit_res = maybe_call_fit(
              ^^^^^^^^^^^^^^^
  File "/usr/local/lib/python3.12/dist-packages/flwr/client/client.py", line 224, in maybe_call_fit
    return client.fit(fit_ins)
           ^^^^^^^^^^^^^^^^^^^
  File "/usr/local/lib/python3.12/dist-packages/flwr/client/numpy_client.py", line 227, in _fit
    results = self.numpy_client.fit(parameters, ins.config)  # type: ignore
              ^^^^^^^^^^^^^^^^^^^^^^^^^^^^^^^^^^^^^^^^^^^^^
TypeError: FederatedClient.fit() takes 2 positional arguments but 3 were given

The above exception was the direct cause of the following exception:

[36mray::ClientAppActor.run()[39m (pid=34043, ip=172.28.0.12, actor_id=68fd605311493b9d27ffc31c01000000, repr=<flwr.simulation.ray_transport.ray_actor.ClientAppActor object at 0x7bee5686ae10>)
           ^^^^^^^^^^^^^^^^^^^^^^^^^^^^^^^^^^^^
           ^^^^^^^^^^^^^^^^^^^^^^^^^^^^^^^
  File "/usr/local/lib/python3.12/dist-packages/flwr/simulation/ray_transport/ray_actor.py", line 64, in run
    raise ClientAppException(str(ex)) from ex
flwr.client.client_app.ClientAppException: 
Exception ClientAppException occurred. Message: FederatedClient.fit() takes 2 positional arguments but 3 were given

[2025-10-04 13:20:33,995][flwr][ERROR] - An exception was raised when processing a message by RayBackend
[2025-10-04 13:20:33,996][flwr][ERROR] - [36mray::ClientAppActor.run()[39m (pid=34043, ip=172.28.0.12, actor_id=68fd605311493b9d27ffc31c01000000, repr=<flwr.simulation.ray_transport.ray_actor.ClientAppActor object at 0x7bee5686ae10>)
                  ^^^^^^^^^^^^^^^^^^^^^^^^^^^^^^^^^^^^^
  File "/usr/local/lib/python3.12/dist-packages/flwr/client/client_app.py", line 144, in __call__
    return self._call(message, context)
           ^^^^^^^^^^^^^^^^^^^^^^^^^^^^
  File "/usr/local/lib/python3.12/dist-packages/flwr/client/client_app.py", line 128, in ffn
    out_message = handle_legacy_message_from_msgtype(
                  ^^^^^^^^^^^^^^^^^^^^^^^^^^^^^^^^^^^
  File "/usr/local/lib/python3.12/dist-packages/flwr/client/message_handler/message_handler.py", line 128, in handle_legacy_message_from_msgtype
    fit_res = maybe_call_fit(
              ^^^^^^^^^^^^^^^
  File "/usr/local/lib/python3.12/dist-packages/flwr/client/client.py", line 224, in maybe_call_fit
    return client.fit(fit_ins)
           ^^^^^^^^^^^^^^^^^^^
  File "/usr/local/lib/python3.12/dist-packages/flwr/client/numpy_client.py", line 227, in _fit
    results = self.numpy_client.fit(parameters, ins.config)  # type: ignore
              ^^^^^^^^^^^^^^^^^^^^^^^^^^^^^^^^^^^^^^^^^^^^^
TypeError: FederatedClient.fit() takes 2 positional arguments but 3 were given

The above exception was the direct cause of the following exception:

[36mray::ClientAppActor.run()[39m (pid=34043, ip=172.28.0.12, actor_id=68fd605311493b9d27ffc31c01000000, repr=<flwr.simulation.ray_transport.ray_actor.ClientAppActor object at 0x7bee5686ae10>)
           ^^^^^^^^^^^^^^^^^^^^^^^^^^^^^^^^^^^^
           ^^^^^^^^^^^^^^^^^^^^^^^^^^^^^^^
  File "/usr/local/lib/python3.12/dist-packages/flwr/simulation/ray_transport/ray_actor.py", line 64, in run
    raise ClientAppException(str(ex)) from ex
flwr.client.client_app.ClientAppException: 
Exception ClientAppException occurred. Message: FederatedClient.fit() takes 2 positional arguments but 3 were given
[2025-10-04 13:20:33,998][flwr][ERROR] - Traceback (most recent call last):
  File "/usr/local/lib/python3.12/dist-packages/flwr/server/superlink/fleet/vce/vce_api.py", line 111, in worker
    out_mssg, updated_context = backend.process_message(message, context)
                                ^^^^^^^^^^^^^^^^^^^^^^^^^^^^^^^^^^^^^^^^^
  File "/usr/local/lib/python3.12/dist-packages/flwr/server/superlink/fleet/vce/backend/raybackend.py", line 189, in process_message
    raise ex
  File "/usr/local/lib/python3.12/dist-packages/flwr/server/superlink/fleet/vce/backend/raybackend.py", line 176, in process_message
    ) = self.pool.fetch_result_and_return_actor_to_pool(future)
        ^^^^^^^^^^^^^^^^^^^^^^^^^^^^^^^^^^^^^^^^^^^^^^^^^^^^^^^
  File "/usr/local/lib/python3.12/dist-packages/flwr/simulation/ray_transport/ray_actor.py", line 480, in fetch_result_and_return_actor_to_pool
    _, out_mssg, updated_context = ray.get(future)
                                   ^^^^^^^^^^^^^^^
  File "/usr/local/lib/python3.12/dist-packages/ray/_private/auto_init_hook.py", line 21, in auto_init_wrapper
    return fn(*args, **kwargs)
           ^^^^^^^^^^^^^^^^^^^
  File "/usr/local/lib/python3.12/dist-packages/ray/_private/client_mode_hook.py", line 103, in wrapper
    return func(*args, **kwargs)
           ^^^^^^^^^^^^^^^^^^^^^
  File "/usr/local/lib/python3.12/dist-packages/ray/_private/worker.py", line 2639, in get
    values, debugger_breakpoint = worker.get_objects(object_refs, timeout=timeout)
                                  ^^^^^^^^^^^^^^^^^^^^^^^^^^^^^^^^^^^^^^^^^^^^^^^^
  File "/usr/local/lib/python3.12/dist-packages/ray/_private/worker.py", line 864, in get_objects
    raise value.as_instanceof_cause()
ray.exceptions.RayTaskError(ClientAppException): [36mray::ClientAppActor.run()[39m (pid=34043, ip=172.28.0.12, actor_id=68fd605311493b9d27ffc31c01000000, repr=<flwr.simulation.ray_transport.ray_actor.ClientAppActor object at 0x7bee5686ae10>)
                  ^^^^^^^^^^^^^^^^^^^^^^^^^^^^^^^^^^^^^
  File "/usr/local/lib/python3.12/dist-packages/flwr/client/client_app.py", line 144, in __call__
    return self._call(message, context)
           ^^^^^^^^^^^^^^^^^^^^^^^^^^^^
  File "/usr/local/lib/python3.12/dist-packages/flwr/client/client_app.py", line 128, in ffn
    out_message = handle_legacy_message_from_msgtype(
                  ^^^^^^^^^^^^^^^^^^^^^^^^^^^^^^^^^^^
  File "/usr/local/lib/python3.12/dist-packages/flwr/client/message_handler/message_handler.py", line 128, in handle_legacy_message_from_msgtype
    fit_res = maybe_call_fit(
              ^^^^^^^^^^^^^^^
  File "/usr/local/lib/python3.12/dist-packages/flwr/client/client.py", line 224, in maybe_call_fit
    return client.fit(fit_ins)
           ^^^^^^^^^^^^^^^^^^^
  File "/usr/local/lib/python3.12/dist-packages/flwr/client/numpy_client.py", line 227, in _fit
    results = self.numpy_client.fit(parameters, ins.config)  # type: ignore
              ^^^^^^^^^^^^^^^^^^^^^^^^^^^^^^^^^^^^^^^^^^^^^
TypeError: FederatedClient.fit() takes 2 positional arguments but 3 were given

The above exception was the direct cause of the following exception:

[36mray::ClientAppActor.run()[39m (pid=34043, ip=172.28.0.12, actor_id=68fd605311493b9d27ffc31c01000000, repr=<flwr.simulation.ray_transport.ray_actor.ClientAppActor object at 0x7bee5686ae10>)
           ^^^^^^^^^^^^^^^^^^^^^^^^^^^^^^^^^^^^
           ^^^^^^^^^^^^^^^^^^^^^^^^^^^^^^^
  File "/usr/local/lib/python3.12/dist-packages/flwr/simulation/ray_transport/ray_actor.py", line 64, in run
    raise ClientAppException(str(ex)) from ex
flwr.client.client_app.ClientAppException: 
Exception ClientAppException occurred. Message: FederatedClient.fit() takes 2 positional arguments but 3 were given

[2025-10-04 13:20:34,087][flwr][INFO] - aggregate_fit: received 0 results and 3 failures
[2025-10-04 13:20:34,087][flwr][INFO] - configure_evaluate: strategy sampled 3 clients (out of 3)
[2025-10-04 13:20:58,811][flwr][INFO] - aggregate_evaluate: received 3 results and 0 failures
[2025-10-04 13:20:58,864][flwr][INFO] - 
[2025-10-04 13:20:58,864][flwr][INFO] - [ROUND 2]
[2025-10-04 13:20:58,864][flwr][INFO] - configure_fit: strategy sampled 3 clients (out of 3)
[2025-10-04 13:20:59,470][flwr][ERROR] - An exception was raised when processing a message by RayBackend
[2025-10-04 13:20:59,471][flwr][ERROR] - [36mray::ClientAppActor.run()[39m (pid=34043, ip=172.28.0.12, actor_id=68fd605311493b9d27ffc31c01000000, repr=<flwr.simulation.ray_transport.ray_actor.ClientAppActor object at 0x7bee5686ae10>)
                  ^^^^^^^^^^^^^^^^^^^^^^^^^^^^^^^^^^^^^
  File "/usr/local/lib/python3.12/dist-packages/flwr/client/client_app.py", line 144, in __call__
    return self._call(message, context)
           ^^^^^^^^^^^^^^^^^^^^^^^^^^^^
  File "/usr/local/lib/python3.12/dist-packages/flwr/client/client_app.py", line 128, in ffn
    out_message = handle_legacy_message_from_msgtype(
                  ^^^^^^^^^^^^^^^^^^^^^^^^^^^^^^^^^^^
  File "/usr/local/lib/python3.12/dist-packages/flwr/client/message_handler/message_handler.py", line 128, in handle_legacy_message_from_msgtype
    fit_res = maybe_call_fit(
              ^^^^^^^^^^^^^^^
  File "/usr/local/lib/python3.12/dist-packages/flwr/client/client.py", line 224, in maybe_call_fit
    return client.fit(fit_ins)
           ^^^^^^^^^^^^^^^^^^^
  File "/usr/local/lib/python3.12/dist-packages/flwr/client/numpy_client.py", line 227, in _fit
    results = self.numpy_client.fit(parameters, ins.config)  # type: ignore
              ^^^^^^^^^^^^^^^^^^^^^^^^^^^^^^^^^^^^^^^^^^^^^
TypeError: FederatedClient.fit() takes 2 positional arguments but 3 were given

The above exception was the direct cause of the following exception:

[36mray::ClientAppActor.run()[39m (pid=34043, ip=172.28.0.12, actor_id=68fd605311493b9d27ffc31c01000000, repr=<flwr.simulation.ray_transport.ray_actor.ClientAppActor object at 0x7bee5686ae10>)
           ^^^^^^^^^^^^^^^^^^^^^^^^^^^^^^^^^^^^
           ^^^^^^^^^^^^^^^^^^^^^^^^^^^^^^^
  File "/usr/local/lib/python3.12/dist-packages/flwr/simulation/ray_transport/ray_actor.py", line 64, in run
    raise ClientAppException(str(ex)) from ex
flwr.client.client_app.ClientAppException: 
Exception ClientAppException occurred. Message: FederatedClient.fit() takes 2 positional arguments but 3 were given
[2025-10-04 13:20:59,472][flwr][ERROR] - Traceback (most recent call last):
  File "/usr/local/lib/python3.12/dist-packages/flwr/server/superlink/fleet/vce/vce_api.py", line 111, in worker
    out_mssg, updated_context = backend.process_message(message, context)
                                ^^^^^^^^^^^^^^^^^^^^^^^^^^^^^^^^^^^^^^^^^
  File "/usr/local/lib/python3.12/dist-packages/flwr/server/superlink/fleet/vce/backend/raybackend.py", line 189, in process_message
    raise ex
  File "/usr/local/lib/python3.12/dist-packages/flwr/server/superlink/fleet/vce/backend/raybackend.py", line 176, in process_message
    ) = self.pool.fetch_result_and_return_actor_to_pool(future)
        ^^^^^^^^^^^^^^^^^^^^^^^^^^^^^^^^^^^^^^^^^^^^^^^^^^^^^^^
  File "/usr/local/lib/python3.12/dist-packages/flwr/simulation/ray_transport/ray_actor.py", line 480, in fetch_result_and_return_actor_to_pool
    _, out_mssg, updated_context = ray.get(future)
                                   ^^^^^^^^^^^^^^^
  File "/usr/local/lib/python3.12/dist-packages/ray/_private/auto_init_hook.py", line 21, in auto_init_wrapper
    return fn(*args, **kwargs)
           ^^^^^^^^^^^^^^^^^^^
  File "/usr/local/lib/python3.12/dist-packages/ray/_private/client_mode_hook.py", line 103, in wrapper
    return func(*args, **kwargs)
           ^^^^^^^^^^^^^^^^^^^^^
  File "/usr/local/lib/python3.12/dist-packages/ray/_private/worker.py", line 2639, in get
    values, debugger_breakpoint = worker.get_objects(object_refs, timeout=timeout)
                                  ^^^^^^^^^^^^^^^^^^^^^^^^^^^^^^^^^^^^^^^^^^^^^^^^
  File "/usr/local/lib/python3.12/dist-packages/ray/_private/worker.py", line 864, in get_objects
    raise value.as_instanceof_cause()
ray.exceptions.RayTaskError(ClientAppException): [36mray::ClientAppActor.run()[39m (pid=34043, ip=172.28.0.12, actor_id=68fd605311493b9d27ffc31c01000000, repr=<flwr.simulation.ray_transport.ray_actor.ClientAppActor object at 0x7bee5686ae10>)
                  ^^^^^^^^^^^^^^^^^^^^^^^^^^^^^^^^^^^^^
  File "/usr/local/lib/python3.12/dist-packages/flwr/client/client_app.py", line 144, in __call__
    return self._call(message, context)
           ^^^^^^^^^^^^^^^^^^^^^^^^^^^^
  File "/usr/local/lib/python3.12/dist-packages/flwr/client/client_app.py", line 128, in ffn
    out_message = handle_legacy_message_from_msgtype(
                  ^^^^^^^^^^^^^^^^^^^^^^^^^^^^^^^^^^^
  File "/usr/local/lib/python3.12/dist-packages/flwr/client/message_handler/message_handler.py", line 128, in handle_legacy_message_from_msgtype
    fit_res = maybe_call_fit(
              ^^^^^^^^^^^^^^^
  File "/usr/local/lib/python3.12/dist-packages/flwr/client/client.py", line 224, in maybe_call_fit
    return client.fit(fit_ins)
           ^^^^^^^^^^^^^^^^^^^
  File "/usr/local/lib/python3.12/dist-packages/flwr/client/numpy_client.py", line 227, in _fit
    results = self.numpy_client.fit(parameters, ins.config)  # type: ignore
              ^^^^^^^^^^^^^^^^^^^^^^^^^^^^^^^^^^^^^^^^^^^^^
TypeError: FederatedClient.fit() takes 2 positional arguments but 3 were given

The above exception was the direct cause of the following exception:

[36mray::ClientAppActor.run()[39m (pid=34043, ip=172.28.0.12, actor_id=68fd605311493b9d27ffc31c01000000, repr=<flwr.simulation.ray_transport.ray_actor.ClientAppActor object at 0x7bee5686ae10>)
           ^^^^^^^^^^^^^^^^^^^^^^^^^^^^^^^^^^^^
           ^^^^^^^^^^^^^^^^^^^^^^^^^^^^^^^
  File "/usr/local/lib/python3.12/dist-packages/flwr/simulation/ray_transport/ray_actor.py", line 64, in run
    raise ClientAppException(str(ex)) from ex
flwr.client.client_app.ClientAppException: 
Exception ClientAppException occurred. Message: FederatedClient.fit() takes 2 positional arguments but 3 were given

[2025-10-04 13:21:00,106][flwr][ERROR] - An exception was raised when processing a message by RayBackend
[2025-10-04 13:21:00,106][flwr][ERROR] - [36mray::ClientAppActor.run()[39m (pid=34043, ip=172.28.0.12, actor_id=68fd605311493b9d27ffc31c01000000, repr=<flwr.simulation.ray_transport.ray_actor.ClientAppActor object at 0x7bee5686ae10>)
                  ^^^^^^^^^^^^^^^^^^^^^^^^^^^^^^^^^^^^^
  File "/usr/local/lib/python3.12/dist-packages/flwr/client/client_app.py", line 144, in __call__
    return self._call(message, context)
           ^^^^^^^^^^^^^^^^^^^^^^^^^^^^
  File "/usr/local/lib/python3.12/dist-packages/flwr/client/client_app.py", line 128, in ffn
    out_message = handle_legacy_message_from_msgtype(
                  ^^^^^^^^^^^^^^^^^^^^^^^^^^^^^^^^^^^
  File "/usr/local/lib/python3.12/dist-packages/flwr/client/message_handler/message_handler.py", line 128, in handle_legacy_message_from_msgtype
    fit_res = maybe_call_fit(
              ^^^^^^^^^^^^^^^
  File "/usr/local/lib/python3.12/dist-packages/flwr/client/client.py", line 224, in maybe_call_fit
    return client.fit(fit_ins)
           ^^^^^^^^^^^^^^^^^^^
  File "/usr/local/lib/python3.12/dist-packages/flwr/client/numpy_client.py", line 227, in _fit
    results = self.numpy_client.fit(parameters, ins.config)  # type: ignore
              ^^^^^^^^^^^^^^^^^^^^^^^^^^^^^^^^^^^^^^^^^^^^^
TypeError: FederatedClient.fit() takes 2 positional arguments but 3 were given

The above exception was the direct cause of the following exception:

[36mray::ClientAppActor.run()[39m (pid=34043, ip=172.28.0.12, actor_id=68fd605311493b9d27ffc31c01000000, repr=<flwr.simulation.ray_transport.ray_actor.ClientAppActor object at 0x7bee5686ae10>)
           ^^^^^^^^^^^^^^^^^^^^^^^^^^^^^^^^^^^^
           ^^^^^^^^^^^^^^^^^^^^^^^^^^^^^^^
  File "/usr/local/lib/python3.12/dist-packages/flwr/simulation/ray_transport/ray_actor.py", line 64, in run
    raise ClientAppException(str(ex)) from ex
flwr.client.client_app.ClientAppException: 
Exception ClientAppException occurred. Message: FederatedClient.fit() takes 2 positional arguments but 3 were given
[2025-10-04 13:21:00,107][flwr][ERROR] - Traceback (most recent call last):
  File "/usr/local/lib/python3.12/dist-packages/flwr/server/superlink/fleet/vce/vce_api.py", line 111, in worker
    out_mssg, updated_context = backend.process_message(message, context)
                                ^^^^^^^^^^^^^^^^^^^^^^^^^^^^^^^^^^^^^^^^^
  File "/usr/local/lib/python3.12/dist-packages/flwr/server/superlink/fleet/vce/backend/raybackend.py", line 189, in process_message
    raise ex
  File "/usr/local/lib/python3.12/dist-packages/flwr/server/superlink/fleet/vce/backend/raybackend.py", line 176, in process_message
    ) = self.pool.fetch_result_and_return_actor_to_pool(future)
        ^^^^^^^^^^^^^^^^^^^^^^^^^^^^^^^^^^^^^^^^^^^^^^^^^^^^^^^
  File "/usr/local/lib/python3.12/dist-packages/flwr/simulation/ray_transport/ray_actor.py", line 480, in fetch_result_and_return_actor_to_pool
    _, out_mssg, updated_context = ray.get(future)
                                   ^^^^^^^^^^^^^^^
  File "/usr/local/lib/python3.12/dist-packages/ray/_private/auto_init_hook.py", line 21, in auto_init_wrapper
    return fn(*args, **kwargs)
           ^^^^^^^^^^^^^^^^^^^
  File "/usr/local/lib/python3.12/dist-packages/ray/_private/client_mode_hook.py", line 103, in wrapper
    return func(*args, **kwargs)
           ^^^^^^^^^^^^^^^^^^^^^
  File "/usr/local/lib/python3.12/dist-packages/ray/_private/worker.py", line 2639, in get
    values, debugger_breakpoint = worker.get_objects(object_refs, timeout=timeout)
                                  ^^^^^^^^^^^^^^^^^^^^^^^^^^^^^^^^^^^^^^^^^^^^^^^^
  File "/usr/local/lib/python3.12/dist-packages/ray/_private/worker.py", line 864, in get_objects
    raise value.as_instanceof_cause()
ray.exceptions.RayTaskError(ClientAppException): [36mray::ClientAppActor.run()[39m (pid=34043, ip=172.28.0.12, actor_id=68fd605311493b9d27ffc31c01000000, repr=<flwr.simulation.ray_transport.ray_actor.ClientAppActor object at 0x7bee5686ae10>)
                  ^^^^^^^^^^^^^^^^^^^^^^^^^^^^^^^^^^^^^
  File "/usr/local/lib/python3.12/dist-packages/flwr/client/client_app.py", line 144, in __call__
    return self._call(message, context)
           ^^^^^^^^^^^^^^^^^^^^^^^^^^^^
  File "/usr/local/lib/python3.12/dist-packages/flwr/client/client_app.py", line 128, in ffn
    out_message = handle_legacy_message_from_msgtype(
                  ^^^^^^^^^^^^^^^^^^^^^^^^^^^^^^^^^^^
  File "/usr/local/lib/python3.12/dist-packages/flwr/client/message_handler/message_handler.py", line 128, in handle_legacy_message_from_msgtype
    fit_res = maybe_call_fit(
              ^^^^^^^^^^^^^^^
  File "/usr/local/lib/python3.12/dist-packages/flwr/client/client.py", line 224, in maybe_call_fit
    return client.fit(fit_ins)
           ^^^^^^^^^^^^^^^^^^^
  File "/usr/local/lib/python3.12/dist-packages/flwr/client/numpy_client.py", line 227, in _fit
    results = self.numpy_client.fit(parameters, ins.config)  # type: ignore
              ^^^^^^^^^^^^^^^^^^^^^^^^^^^^^^^^^^^^^^^^^^^^^
TypeError: FederatedClient.fit() takes 2 positional arguments but 3 were given

The above exception was the direct cause of the following exception:

[36mray::ClientAppActor.run()[39m (pid=34043, ip=172.28.0.12, actor_id=68fd605311493b9d27ffc31c01000000, repr=<flwr.simulation.ray_transport.ray_actor.ClientAppActor object at 0x7bee5686ae10>)
           ^^^^^^^^^^^^^^^^^^^^^^^^^^^^^^^^^^^^
           ^^^^^^^^^^^^^^^^^^^^^^^^^^^^^^^
  File "/usr/local/lib/python3.12/dist-packages/flwr/simulation/ray_transport/ray_actor.py", line 64, in run
    raise ClientAppException(str(ex)) from ex
flwr.client.client_app.ClientAppException: 
Exception ClientAppException occurred. Message: FederatedClient.fit() takes 2 positional arguments but 3 were given

[2025-10-04 13:21:00,688][flwr][ERROR] - An exception was raised when processing a message by RayBackend
[2025-10-04 13:21:00,689][flwr][ERROR] - [36mray::ClientAppActor.run()[39m (pid=34043, ip=172.28.0.12, actor_id=68fd605311493b9d27ffc31c01000000, repr=<flwr.simulation.ray_transport.ray_actor.ClientAppActor object at 0x7bee5686ae10>)
                  ^^^^^^^^^^^^^^^^^^^^^^^^^^^^^^^^^^^^^
  File "/usr/local/lib/python3.12/dist-packages/flwr/client/client_app.py", line 144, in __call__
    return self._call(message, context)
           ^^^^^^^^^^^^^^^^^^^^^^^^^^^^
  File "/usr/local/lib/python3.12/dist-packages/flwr/client/client_app.py", line 128, in ffn
    out_message = handle_legacy_message_from_msgtype(
                  ^^^^^^^^^^^^^^^^^^^^^^^^^^^^^^^^^^^
  File "/usr/local/lib/python3.12/dist-packages/flwr/client/message_handler/message_handler.py", line 128, in handle_legacy_message_from_msgtype
    fit_res = maybe_call_fit(
              ^^^^^^^^^^^^^^^
  File "/usr/local/lib/python3.12/dist-packages/flwr/client/client.py", line 224, in maybe_call_fit
    return client.fit(fit_ins)
           ^^^^^^^^^^^^^^^^^^^
  File "/usr/local/lib/python3.12/dist-packages/flwr/client/numpy_client.py", line 227, in _fit
    results = self.numpy_client.fit(parameters, ins.config)  # type: ignore
              ^^^^^^^^^^^^^^^^^^^^^^^^^^^^^^^^^^^^^^^^^^^^^
TypeError: FederatedClient.fit() takes 2 positional arguments but 3 were given

The above exception was the direct cause of the following exception:

[36mray::ClientAppActor.run()[39m (pid=34043, ip=172.28.0.12, actor_id=68fd605311493b9d27ffc31c01000000, repr=<flwr.simulation.ray_transport.ray_actor.ClientAppActor object at 0x7bee5686ae10>)
           ^^^^^^^^^^^^^^^^^^^^^^^^^^^^^^^^^^^^
           ^^^^^^^^^^^^^^^^^^^^^^^^^^^^^^^
  File "/usr/local/lib/python3.12/dist-packages/flwr/simulation/ray_transport/ray_actor.py", line 64, in run
    raise ClientAppException(str(ex)) from ex
flwr.client.client_app.ClientAppException: 
Exception ClientAppException occurred. Message: FederatedClient.fit() takes 2 positional arguments but 3 were given
[2025-10-04 13:21:00,693][flwr][ERROR] - Traceback (most recent call last):
  File "/usr/local/lib/python3.12/dist-packages/flwr/server/superlink/fleet/vce/vce_api.py", line 111, in worker
    out_mssg, updated_context = backend.process_message(message, context)
                                ^^^^^^^^^^^^^^^^^^^^^^^^^^^^^^^^^^^^^^^^^
  File "/usr/local/lib/python3.12/dist-packages/flwr/server/superlink/fleet/vce/backend/raybackend.py", line 189, in process_message
    raise ex
  File "/usr/local/lib/python3.12/dist-packages/flwr/server/superlink/fleet/vce/backend/raybackend.py", line 176, in process_message
    ) = self.pool.fetch_result_and_return_actor_to_pool(future)
        ^^^^^^^^^^^^^^^^^^^^^^^^^^^^^^^^^^^^^^^^^^^^^^^^^^^^^^^
  File "/usr/local/lib/python3.12/dist-packages/flwr/simulation/ray_transport/ray_actor.py", line 480, in fetch_result_and_return_actor_to_pool
    _, out_mssg, updated_context = ray.get(future)
                                   ^^^^^^^^^^^^^^^
  File "/usr/local/lib/python3.12/dist-packages/ray/_private/auto_init_hook.py", line 21, in auto_init_wrapper
    return fn(*args, **kwargs)
           ^^^^^^^^^^^^^^^^^^^
  File "/usr/local/lib/python3.12/dist-packages/ray/_private/client_mode_hook.py", line 103, in wrapper
    return func(*args, **kwargs)
           ^^^^^^^^^^^^^^^^^^^^^
  File "/usr/local/lib/python3.12/dist-packages/ray/_private/worker.py", line 2639, in get
    values, debugger_breakpoint = worker.get_objects(object_refs, timeout=timeout)
                                  ^^^^^^^^^^^^^^^^^^^^^^^^^^^^^^^^^^^^^^^^^^^^^^^^
  File "/usr/local/lib/python3.12/dist-packages/ray/_private/worker.py", line 864, in get_objects
    raise value.as_instanceof_cause()
ray.exceptions.RayTaskError(ClientAppException): [36mray::ClientAppActor.run()[39m (pid=34043, ip=172.28.0.12, actor_id=68fd605311493b9d27ffc31c01000000, repr=<flwr.simulation.ray_transport.ray_actor.ClientAppActor object at 0x7bee5686ae10>)
                  ^^^^^^^^^^^^^^^^^^^^^^^^^^^^^^^^^^^^^
  File "/usr/local/lib/python3.12/dist-packages/flwr/client/client_app.py", line 144, in __call__
    return self._call(message, context)
           ^^^^^^^^^^^^^^^^^^^^^^^^^^^^
  File "/usr/local/lib/python3.12/dist-packages/flwr/client/client_app.py", line 128, in ffn
    out_message = handle_legacy_message_from_msgtype(
                  ^^^^^^^^^^^^^^^^^^^^^^^^^^^^^^^^^^^
  File "/usr/local/lib/python3.12/dist-packages/flwr/client/message_handler/message_handler.py", line 128, in handle_legacy_message_from_msgtype
    fit_res = maybe_call_fit(
              ^^^^^^^^^^^^^^^
  File "/usr/local/lib/python3.12/dist-packages/flwr/client/client.py", line 224, in maybe_call_fit
    return client.fit(fit_ins)
           ^^^^^^^^^^^^^^^^^^^
  File "/usr/local/lib/python3.12/dist-packages/flwr/client/numpy_client.py", line 227, in _fit
    results = self.numpy_client.fit(parameters, ins.config)  # type: ignore
              ^^^^^^^^^^^^^^^^^^^^^^^^^^^^^^^^^^^^^^^^^^^^^
TypeError: FederatedClient.fit() takes 2 positional arguments but 3 were given

The above exception was the direct cause of the following exception:

[36mray::ClientAppActor.run()[39m (pid=34043, ip=172.28.0.12, actor_id=68fd605311493b9d27ffc31c01000000, repr=<flwr.simulation.ray_transport.ray_actor.ClientAppActor object at 0x7bee5686ae10>)
           ^^^^^^^^^^^^^^^^^^^^^^^^^^^^^^^^^^^^
           ^^^^^^^^^^^^^^^^^^^^^^^^^^^^^^^
  File "/usr/local/lib/python3.12/dist-packages/flwr/simulation/ray_transport/ray_actor.py", line 64, in run
    raise ClientAppException(str(ex)) from ex
flwr.client.client_app.ClientAppException: 
Exception ClientAppException occurred. Message: FederatedClient.fit() takes 2 positional arguments but 3 were given

[2025-10-04 13:21:00,786][flwr][INFO] - aggregate_fit: received 0 results and 3 failures
[2025-10-04 13:21:00,791][flwr][INFO] - configure_evaluate: strategy sampled 3 clients (out of 3)
[2025-10-04 13:21:11,819][flwr][DEBUG] - Terminated 0 actors
