[2025-10-04 13:36:35,478][flwr][DEBUG] - Pre-registering run with id 8113755851801532465
[2025-10-04 13:36:35,479][flwr][DEBUG] - Using InMemoryState
[2025-10-04 13:36:35,479][flwr][DEBUG] - Using InMemoryState
[2025-10-04 13:36:35,481][flwr][DEBUG] - Using InMemoryState
[2025-10-04 13:36:35,481][flwr][DEBUG] - Registered 3 nodes
[2025-10-04 13:36:35,481][flwr][DEBUG] - Supported backends: ['ray']
[2025-10-04 13:36:35,484][flwr][DEBUG] - Initialising: RayBackend
[2025-10-04 13:36:35,485][flwr][DEBUG] - Backend config: {'num_cpus': 2, 'num_gpus': 0.0, 'init_args': {'logging_level': 30, 'log_to_driver': True}, 'client_resources': {'num_cpus': 2, 'num_gpus': 0}, 'actor': {'tensorflow': 0}}
[2025-10-04 13:36:35,654][flwr][INFO] - Starting Flower ServerApp, config: num_rounds=3, no round_timeout
[2025-10-04 13:36:35,656][flwr][INFO] - 
[2025-10-04 13:36:35,657][flwr][INFO] - [INIT]
[2025-10-04 13:36:35,657][flwr][INFO] - Requesting initial parameters from one random client
[2025-10-04 13:36:52,816][flwr][DEBUG] - Constructed ActorPool with: 1 actors
[2025-10-04 13:36:52,817][flwr][DEBUG] - Using InMemoryState
[2025-10-04 13:37:16,759][flwr][INFO] - Received initial parameters from one random client
[2025-10-04 13:37:16,759][flwr][INFO] - Starting evaluation of initial global parameters
[2025-10-04 13:37:16,759][flwr][INFO] - Evaluation returned no results (`None`)
[2025-10-04 13:37:16,759][flwr][INFO] - 
[2025-10-04 13:37:16,759][flwr][INFO] - [ROUND 1]
[2025-10-04 13:37:16,760][flwr][INFO] - configure_fit: strategy sampled 3 clients (out of 3)
[2025-10-04 13:37:18,064][flwr][ERROR] - An exception was raised when processing a message by RayBackend
[2025-10-04 13:37:18,064][flwr][ERROR] - [36mray::ClientAppActor.run()[39m (pid=39710, ip=172.28.0.12, actor_id=386d1b25a36388b25c53d2e501000000, repr=<flwr.simulation.ray_transport.ray_actor.ClientAppActor object at 0x7ae882f2f770>)
                  ^^^^^^^^^^^^^^^^^^^^^^^^^^^^^^^^^^^^^
  File "/usr/local/lib/python3.12/dist-packages/flwr/client/client_app.py", line 144, in __call__
    return self._call(message, context)
           ^^^^^^^^^^^^^^^^^^^^^^^^^^^^
  File "/usr/local/lib/python3.12/dist-packages/flwr/client/client_app.py", line 128, in ffn
    out_message = handle_legacy_message_from_msgtype(
                  ^^^^^^^^^^^^^^^^^^^^^^^^^^^^^^^^^^^
  File "/usr/local/lib/python3.12/dist-packages/flwr/client/message_handler/message_handler.py", line 128, in handle_legacy_message_from_msgtype
    fit_res = maybe_call_fit(
              ^^^^^^^^^^^^^^^
  File "/usr/local/lib/python3.12/dist-packages/flwr/client/client.py", line 224, in maybe_call_fit
    return client.fit(fit_ins)
           ^^^^^^^^^^^^^^^^^^^
  File "/usr/local/lib/python3.12/dist-packages/flwr/client/numpy_client.py", line 227, in _fit
    results = self.numpy_client.fit(parameters, ins.config)  # type: ignore
              ^^^^^^^^^^^^^^^^^^^^^^^^^^^^^^^^^^^^^^^^^^^^^
  File "/content/cluster-CDCSF/fedprox/fedprox/client.py", line 254, in fit
    raise e
  File "/content/cluster-CDCSF/fedprox/fedprox/client.py", line 222, in fit
    self.train(self.net, self.traindata, self.client_id, epochs=self.local_epochs, simulate_delay=simulate_delay)
               ^^^^^^^^
AttributeError: 'FederatedClient' object has no attribute 'net'

The above exception was the direct cause of the following exception:

[36mray::ClientAppActor.run()[39m (pid=39710, ip=172.28.0.12, actor_id=386d1b25a36388b25c53d2e501000000, repr=<flwr.simulation.ray_transport.ray_actor.ClientAppActor object at 0x7ae882f2f770>)
           ^^^^^^^^^^^^^^^^^^^^^^^^^^^^^^^^^^^^
           ^^^^^^^^^^^^^^^^^^^^^^^^^^^^^^^
  File "/usr/local/lib/python3.12/dist-packages/flwr/simulation/ray_transport/ray_actor.py", line 64, in run
    raise ClientAppException(str(ex)) from ex
flwr.client.client_app.ClientAppException: 
Exception ClientAppException occurred. Message: 'FederatedClient' object has no attribute 'net'
[2025-10-04 13:37:18,067][flwr][ERROR] - Traceback (most recent call last):
  File "/usr/local/lib/python3.12/dist-packages/flwr/server/superlink/fleet/vce/vce_api.py", line 111, in worker
    out_mssg, updated_context = backend.process_message(message, context)
                                ^^^^^^^^^^^^^^^^^^^^^^^^^^^^^^^^^^^^^^^^^
  File "/usr/local/lib/python3.12/dist-packages/flwr/server/superlink/fleet/vce/backend/raybackend.py", line 189, in process_message
    raise ex
  File "/usr/local/lib/python3.12/dist-packages/flwr/server/superlink/fleet/vce/backend/raybackend.py", line 176, in process_message
    ) = self.pool.fetch_result_and_return_actor_to_pool(future)
        ^^^^^^^^^^^^^^^^^^^^^^^^^^^^^^^^^^^^^^^^^^^^^^^^^^^^^^^
  File "/usr/local/lib/python3.12/dist-packages/flwr/simulation/ray_transport/ray_actor.py", line 480, in fetch_result_and_return_actor_to_pool
    _, out_mssg, updated_context = ray.get(future)
                                   ^^^^^^^^^^^^^^^
  File "/usr/local/lib/python3.12/dist-packages/ray/_private/auto_init_hook.py", line 21, in auto_init_wrapper
    return fn(*args, **kwargs)
           ^^^^^^^^^^^^^^^^^^^
  File "/usr/local/lib/python3.12/dist-packages/ray/_private/client_mode_hook.py", line 103, in wrapper
    return func(*args, **kwargs)
           ^^^^^^^^^^^^^^^^^^^^^
  File "/usr/local/lib/python3.12/dist-packages/ray/_private/worker.py", line 2639, in get
    values, debugger_breakpoint = worker.get_objects(object_refs, timeout=timeout)
                                  ^^^^^^^^^^^^^^^^^^^^^^^^^^^^^^^^^^^^^^^^^^^^^^^^
  File "/usr/local/lib/python3.12/dist-packages/ray/_private/worker.py", line 864, in get_objects
    raise value.as_instanceof_cause()
ray.exceptions.RayTaskError(ClientAppException): [36mray::ClientAppActor.run()[39m (pid=39710, ip=172.28.0.12, actor_id=386d1b25a36388b25c53d2e501000000, repr=<flwr.simulation.ray_transport.ray_actor.ClientAppActor object at 0x7ae882f2f770>)
                  ^^^^^^^^^^^^^^^^^^^^^^^^^^^^^^^^^^^^^
  File "/usr/local/lib/python3.12/dist-packages/flwr/client/client_app.py", line 144, in __call__
    return self._call(message, context)
           ^^^^^^^^^^^^^^^^^^^^^^^^^^^^
  File "/usr/local/lib/python3.12/dist-packages/flwr/client/client_app.py", line 128, in ffn
    out_message = handle_legacy_message_from_msgtype(
                  ^^^^^^^^^^^^^^^^^^^^^^^^^^^^^^^^^^^
  File "/usr/local/lib/python3.12/dist-packages/flwr/client/message_handler/message_handler.py", line 128, in handle_legacy_message_from_msgtype
    fit_res = maybe_call_fit(
              ^^^^^^^^^^^^^^^
  File "/usr/local/lib/python3.12/dist-packages/flwr/client/client.py", line 224, in maybe_call_fit
    return client.fit(fit_ins)
           ^^^^^^^^^^^^^^^^^^^
  File "/usr/local/lib/python3.12/dist-packages/flwr/client/numpy_client.py", line 227, in _fit
    results = self.numpy_client.fit(parameters, ins.config)  # type: ignore
              ^^^^^^^^^^^^^^^^^^^^^^^^^^^^^^^^^^^^^^^^^^^^^
  File "/content/cluster-CDCSF/fedprox/fedprox/client.py", line 254, in fit
    raise e
  File "/content/cluster-CDCSF/fedprox/fedprox/client.py", line 222, in fit
    self.train(self.net, self.traindata, self.client_id, epochs=self.local_epochs, simulate_delay=simulate_delay)
               ^^^^^^^^
AttributeError: 'FederatedClient' object has no attribute 'net'

The above exception was the direct cause of the following exception:

[36mray::ClientAppActor.run()[39m (pid=39710, ip=172.28.0.12, actor_id=386d1b25a36388b25c53d2e501000000, repr=<flwr.simulation.ray_transport.ray_actor.ClientAppActor object at 0x7ae882f2f770>)
           ^^^^^^^^^^^^^^^^^^^^^^^^^^^^^^^^^^^^
           ^^^^^^^^^^^^^^^^^^^^^^^^^^^^^^^
  File "/usr/local/lib/python3.12/dist-packages/flwr/simulation/ray_transport/ray_actor.py", line 64, in run
    raise ClientAppException(str(ex)) from ex
flwr.client.client_app.ClientAppException: 
Exception ClientAppException occurred. Message: 'FederatedClient' object has no attribute 'net'

[2025-10-04 13:37:18,721][flwr][ERROR] - An exception was raised when processing a message by RayBackend
[2025-10-04 13:37:18,721][flwr][ERROR] - [36mray::ClientAppActor.run()[39m (pid=39710, ip=172.28.0.12, actor_id=386d1b25a36388b25c53d2e501000000, repr=<flwr.simulation.ray_transport.ray_actor.ClientAppActor object at 0x7ae882f2f770>)
                  ^^^^^^^^^^^^^^^^^^^^^^^^^^^^^^^^^^^^^
  File "/usr/local/lib/python3.12/dist-packages/flwr/client/client_app.py", line 144, in __call__
    return self._call(message, context)
           ^^^^^^^^^^^^^^^^^^^^^^^^^^^^
  File "/usr/local/lib/python3.12/dist-packages/flwr/client/client_app.py", line 128, in ffn
    out_message = handle_legacy_message_from_msgtype(
                  ^^^^^^^^^^^^^^^^^^^^^^^^^^^^^^^^^^^
  File "/usr/local/lib/python3.12/dist-packages/flwr/client/message_handler/message_handler.py", line 128, in handle_legacy_message_from_msgtype
    fit_res = maybe_call_fit(
              ^^^^^^^^^^^^^^^
  File "/usr/local/lib/python3.12/dist-packages/flwr/client/client.py", line 224, in maybe_call_fit
    return client.fit(fit_ins)
           ^^^^^^^^^^^^^^^^^^^
  File "/usr/local/lib/python3.12/dist-packages/flwr/client/numpy_client.py", line 227, in _fit
    results = self.numpy_client.fit(parameters, ins.config)  # type: ignore
              ^^^^^^^^^^^^^^^^^^^^^^^^^^^^^^^^^^^^^^^^^^^^^
  File "/content/cluster-CDCSF/fedprox/fedprox/client.py", line 254, in fit
    raise e
  File "/content/cluster-CDCSF/fedprox/fedprox/client.py", line 222, in fit
    self.train(self.net, self.traindata, self.client_id, epochs=self.local_epochs, simulate_delay=simulate_delay)
               ^^^^^^^^
AttributeError: 'FederatedClient' object has no attribute 'net'

The above exception was the direct cause of the following exception:

[36mray::ClientAppActor.run()[39m (pid=39710, ip=172.28.0.12, actor_id=386d1b25a36388b25c53d2e501000000, repr=<flwr.simulation.ray_transport.ray_actor.ClientAppActor object at 0x7ae882f2f770>)
           ^^^^^^^^^^^^^^^^^^^^^^^^^^^^^^^^^^^^
           ^^^^^^^^^^^^^^^^^^^^^^^^^^^^^^^
  File "/usr/local/lib/python3.12/dist-packages/flwr/simulation/ray_transport/ray_actor.py", line 64, in run
    raise ClientAppException(str(ex)) from ex
flwr.client.client_app.ClientAppException: 
Exception ClientAppException occurred. Message: 'FederatedClient' object has no attribute 'net'
[2025-10-04 13:37:18,722][flwr][ERROR] - Traceback (most recent call last):
  File "/usr/local/lib/python3.12/dist-packages/flwr/server/superlink/fleet/vce/vce_api.py", line 111, in worker
    out_mssg, updated_context = backend.process_message(message, context)
                                ^^^^^^^^^^^^^^^^^^^^^^^^^^^^^^^^^^^^^^^^^
  File "/usr/local/lib/python3.12/dist-packages/flwr/server/superlink/fleet/vce/backend/raybackend.py", line 189, in process_message
    raise ex
  File "/usr/local/lib/python3.12/dist-packages/flwr/server/superlink/fleet/vce/backend/raybackend.py", line 176, in process_message
    ) = self.pool.fetch_result_and_return_actor_to_pool(future)
        ^^^^^^^^^^^^^^^^^^^^^^^^^^^^^^^^^^^^^^^^^^^^^^^^^^^^^^^
  File "/usr/local/lib/python3.12/dist-packages/flwr/simulation/ray_transport/ray_actor.py", line 480, in fetch_result_and_return_actor_to_pool
    _, out_mssg, updated_context = ray.get(future)
                                   ^^^^^^^^^^^^^^^
  File "/usr/local/lib/python3.12/dist-packages/ray/_private/auto_init_hook.py", line 21, in auto_init_wrapper
    return fn(*args, **kwargs)
           ^^^^^^^^^^^^^^^^^^^
  File "/usr/local/lib/python3.12/dist-packages/ray/_private/client_mode_hook.py", line 103, in wrapper
    return func(*args, **kwargs)
           ^^^^^^^^^^^^^^^^^^^^^
  File "/usr/local/lib/python3.12/dist-packages/ray/_private/worker.py", line 2639, in get
    values, debugger_breakpoint = worker.get_objects(object_refs, timeout=timeout)
                                  ^^^^^^^^^^^^^^^^^^^^^^^^^^^^^^^^^^^^^^^^^^^^^^^^
  File "/usr/local/lib/python3.12/dist-packages/ray/_private/worker.py", line 864, in get_objects
    raise value.as_instanceof_cause()
ray.exceptions.RayTaskError(ClientAppException): [36mray::ClientAppActor.run()[39m (pid=39710, ip=172.28.0.12, actor_id=386d1b25a36388b25c53d2e501000000, repr=<flwr.simulation.ray_transport.ray_actor.ClientAppActor object at 0x7ae882f2f770>)
                  ^^^^^^^^^^^^^^^^^^^^^^^^^^^^^^^^^^^^^
  File "/usr/local/lib/python3.12/dist-packages/flwr/client/client_app.py", line 144, in __call__
    return self._call(message, context)
           ^^^^^^^^^^^^^^^^^^^^^^^^^^^^
  File "/usr/local/lib/python3.12/dist-packages/flwr/client/client_app.py", line 128, in ffn
    out_message = handle_legacy_message_from_msgtype(
                  ^^^^^^^^^^^^^^^^^^^^^^^^^^^^^^^^^^^
  File "/usr/local/lib/python3.12/dist-packages/flwr/client/message_handler/message_handler.py", line 128, in handle_legacy_message_from_msgtype
    fit_res = maybe_call_fit(
              ^^^^^^^^^^^^^^^
  File "/usr/local/lib/python3.12/dist-packages/flwr/client/client.py", line 224, in maybe_call_fit
    return client.fit(fit_ins)
           ^^^^^^^^^^^^^^^^^^^
  File "/usr/local/lib/python3.12/dist-packages/flwr/client/numpy_client.py", line 227, in _fit
    results = self.numpy_client.fit(parameters, ins.config)  # type: ignore
              ^^^^^^^^^^^^^^^^^^^^^^^^^^^^^^^^^^^^^^^^^^^^^
  File "/content/cluster-CDCSF/fedprox/fedprox/client.py", line 254, in fit
    raise e
  File "/content/cluster-CDCSF/fedprox/fedprox/client.py", line 222, in fit
    self.train(self.net, self.traindata, self.client_id, epochs=self.local_epochs, simulate_delay=simulate_delay)
               ^^^^^^^^
AttributeError: 'FederatedClient' object has no attribute 'net'

The above exception was the direct cause of the following exception:

[36mray::ClientAppActor.run()[39m (pid=39710, ip=172.28.0.12, actor_id=386d1b25a36388b25c53d2e501000000, repr=<flwr.simulation.ray_transport.ray_actor.ClientAppActor object at 0x7ae882f2f770>)
           ^^^^^^^^^^^^^^^^^^^^^^^^^^^^^^^^^^^^
           ^^^^^^^^^^^^^^^^^^^^^^^^^^^^^^^
  File "/usr/local/lib/python3.12/dist-packages/flwr/simulation/ray_transport/ray_actor.py", line 64, in run
    raise ClientAppException(str(ex)) from ex
flwr.client.client_app.ClientAppException: 
Exception ClientAppException occurred. Message: 'FederatedClient' object has no attribute 'net'

[2025-10-04 13:37:19,681][flwr][ERROR] - An exception was raised when processing a message by RayBackend
[2025-10-04 13:37:19,681][flwr][ERROR] - [36mray::ClientAppActor.run()[39m (pid=39710, ip=172.28.0.12, actor_id=386d1b25a36388b25c53d2e501000000, repr=<flwr.simulation.ray_transport.ray_actor.ClientAppActor object at 0x7ae882f2f770>)
                  ^^^^^^^^^^^^^^^^^^^^^^^^^^^^^^^^^^^^^
  File "/usr/local/lib/python3.12/dist-packages/flwr/client/client_app.py", line 144, in __call__
    return self._call(message, context)
           ^^^^^^^^^^^^^^^^^^^^^^^^^^^^
  File "/usr/local/lib/python3.12/dist-packages/flwr/client/client_app.py", line 128, in ffn
    out_message = handle_legacy_message_from_msgtype(
                  ^^^^^^^^^^^^^^^^^^^^^^^^^^^^^^^^^^^
  File "/usr/local/lib/python3.12/dist-packages/flwr/client/message_handler/message_handler.py", line 128, in handle_legacy_message_from_msgtype
    fit_res = maybe_call_fit(
              ^^^^^^^^^^^^^^^
  File "/usr/local/lib/python3.12/dist-packages/flwr/client/client.py", line 224, in maybe_call_fit
    return client.fit(fit_ins)
           ^^^^^^^^^^^^^^^^^^^
  File "/usr/local/lib/python3.12/dist-packages/flwr/client/numpy_client.py", line 227, in _fit
    results = self.numpy_client.fit(parameters, ins.config)  # type: ignore
              ^^^^^^^^^^^^^^^^^^^^^^^^^^^^^^^^^^^^^^^^^^^^^
  File "/content/cluster-CDCSF/fedprox/fedprox/client.py", line 254, in fit
    raise e
  File "/content/cluster-CDCSF/fedprox/fedprox/client.py", line 222, in fit
    self.train(self.net, self.traindata, self.client_id, epochs=self.local_epochs, simulate_delay=simulate_delay)
               ^^^^^^^^
AttributeError: 'FederatedClient' object has no attribute 'net'

The above exception was the direct cause of the following exception:

[36mray::ClientAppActor.run()[39m (pid=39710, ip=172.28.0.12, actor_id=386d1b25a36388b25c53d2e501000000, repr=<flwr.simulation.ray_transport.ray_actor.ClientAppActor object at 0x7ae882f2f770>)
           ^^^^^^^^^^^^^^^^^^^^^^^^^^^^^^^^^^^^
           ^^^^^^^^^^^^^^^^^^^^^^^^^^^^^^^
  File "/usr/local/lib/python3.12/dist-packages/flwr/simulation/ray_transport/ray_actor.py", line 64, in run
    raise ClientAppException(str(ex)) from ex
flwr.client.client_app.ClientAppException: 
Exception ClientAppException occurred. Message: 'FederatedClient' object has no attribute 'net'
[2025-10-04 13:37:19,682][flwr][ERROR] - Traceback (most recent call last):
  File "/usr/local/lib/python3.12/dist-packages/flwr/server/superlink/fleet/vce/vce_api.py", line 111, in worker
    out_mssg, updated_context = backend.process_message(message, context)
                                ^^^^^^^^^^^^^^^^^^^^^^^^^^^^^^^^^^^^^^^^^
  File "/usr/local/lib/python3.12/dist-packages/flwr/server/superlink/fleet/vce/backend/raybackend.py", line 189, in process_message
    raise ex
  File "/usr/local/lib/python3.12/dist-packages/flwr/server/superlink/fleet/vce/backend/raybackend.py", line 176, in process_message
    ) = self.pool.fetch_result_and_return_actor_to_pool(future)
        ^^^^^^^^^^^^^^^^^^^^^^^^^^^^^^^^^^^^^^^^^^^^^^^^^^^^^^^
  File "/usr/local/lib/python3.12/dist-packages/flwr/simulation/ray_transport/ray_actor.py", line 480, in fetch_result_and_return_actor_to_pool
    _, out_mssg, updated_context = ray.get(future)
                                   ^^^^^^^^^^^^^^^
  File "/usr/local/lib/python3.12/dist-packages/ray/_private/auto_init_hook.py", line 21, in auto_init_wrapper
    return fn(*args, **kwargs)
           ^^^^^^^^^^^^^^^^^^^
  File "/usr/local/lib/python3.12/dist-packages/ray/_private/client_mode_hook.py", line 103, in wrapper
    return func(*args, **kwargs)
           ^^^^^^^^^^^^^^^^^^^^^
  File "/usr/local/lib/python3.12/dist-packages/ray/_private/worker.py", line 2639, in get
    values, debugger_breakpoint = worker.get_objects(object_refs, timeout=timeout)
                                  ^^^^^^^^^^^^^^^^^^^^^^^^^^^^^^^^^^^^^^^^^^^^^^^^
  File "/usr/local/lib/python3.12/dist-packages/ray/_private/worker.py", line 864, in get_objects
    raise value.as_instanceof_cause()
ray.exceptions.RayTaskError(ClientAppException): [36mray::ClientAppActor.run()[39m (pid=39710, ip=172.28.0.12, actor_id=386d1b25a36388b25c53d2e501000000, repr=<flwr.simulation.ray_transport.ray_actor.ClientAppActor object at 0x7ae882f2f770>)
                  ^^^^^^^^^^^^^^^^^^^^^^^^^^^^^^^^^^^^^
  File "/usr/local/lib/python3.12/dist-packages/flwr/client/client_app.py", line 144, in __call__
    return self._call(message, context)
           ^^^^^^^^^^^^^^^^^^^^^^^^^^^^
  File "/usr/local/lib/python3.12/dist-packages/flwr/client/client_app.py", line 128, in ffn
    out_message = handle_legacy_message_from_msgtype(
                  ^^^^^^^^^^^^^^^^^^^^^^^^^^^^^^^^^^^
  File "/usr/local/lib/python3.12/dist-packages/flwr/client/message_handler/message_handler.py", line 128, in handle_legacy_message_from_msgtype
    fit_res = maybe_call_fit(
              ^^^^^^^^^^^^^^^
  File "/usr/local/lib/python3.12/dist-packages/flwr/client/client.py", line 224, in maybe_call_fit
    return client.fit(fit_ins)
           ^^^^^^^^^^^^^^^^^^^
  File "/usr/local/lib/python3.12/dist-packages/flwr/client/numpy_client.py", line 227, in _fit
    results = self.numpy_client.fit(parameters, ins.config)  # type: ignore
              ^^^^^^^^^^^^^^^^^^^^^^^^^^^^^^^^^^^^^^^^^^^^^
  File "/content/cluster-CDCSF/fedprox/fedprox/client.py", line 254, in fit
    raise e
  File "/content/cluster-CDCSF/fedprox/fedprox/client.py", line 222, in fit
    self.train(self.net, self.traindata, self.client_id, epochs=self.local_epochs, simulate_delay=simulate_delay)
               ^^^^^^^^
AttributeError: 'FederatedClient' object has no attribute 'net'

The above exception was the direct cause of the following exception:

[36mray::ClientAppActor.run()[39m (pid=39710, ip=172.28.0.12, actor_id=386d1b25a36388b25c53d2e501000000, repr=<flwr.simulation.ray_transport.ray_actor.ClientAppActor object at 0x7ae882f2f770>)
           ^^^^^^^^^^^^^^^^^^^^^^^^^^^^^^^^^^^^
           ^^^^^^^^^^^^^^^^^^^^^^^^^^^^^^^
  File "/usr/local/lib/python3.12/dist-packages/flwr/simulation/ray_transport/ray_actor.py", line 64, in run
    raise ClientAppException(str(ex)) from ex
flwr.client.client_app.ClientAppException: 
Exception ClientAppException occurred. Message: 'FederatedClient' object has no attribute 'net'

[2025-10-04 13:37:19,704][flwr][INFO] - aggregate_fit: received 0 results and 3 failures
[2025-10-04 13:37:19,768][flwr][INFO] - configure_evaluate: strategy sampled 3 clients (out of 3)
[2025-10-04 13:37:45,095][flwr][INFO] - aggregate_evaluate: received 3 results and 0 failures
[2025-10-04 13:37:45,147][flwr][INFO] - 
[2025-10-04 13:37:45,147][flwr][INFO] - [ROUND 2]
[2025-10-04 13:37:45,148][flwr][INFO] - configure_fit: strategy sampled 3 clients (out of 3)
[2025-10-04 13:37:45,838][flwr][ERROR] - An exception was raised when processing a message by RayBackend
[2025-10-04 13:37:45,838][flwr][ERROR] - [36mray::ClientAppActor.run()[39m (pid=39710, ip=172.28.0.12, actor_id=386d1b25a36388b25c53d2e501000000, repr=<flwr.simulation.ray_transport.ray_actor.ClientAppActor object at 0x7ae882f2f770>)
                  ^^^^^^^^^^^^^^^^^^^^^^^^^^^^^^^^^^^^^
  File "/usr/local/lib/python3.12/dist-packages/flwr/client/client_app.py", line 144, in __call__
    return self._call(message, context)
           ^^^^^^^^^^^^^^^^^^^^^^^^^^^^
  File "/usr/local/lib/python3.12/dist-packages/flwr/client/client_app.py", line 128, in ffn
    out_message = handle_legacy_message_from_msgtype(
                  ^^^^^^^^^^^^^^^^^^^^^^^^^^^^^^^^^^^
  File "/usr/local/lib/python3.12/dist-packages/flwr/client/message_handler/message_handler.py", line 128, in handle_legacy_message_from_msgtype
    fit_res = maybe_call_fit(
              ^^^^^^^^^^^^^^^
  File "/usr/local/lib/python3.12/dist-packages/flwr/client/client.py", line 224, in maybe_call_fit
    return client.fit(fit_ins)
           ^^^^^^^^^^^^^^^^^^^
  File "/usr/local/lib/python3.12/dist-packages/flwr/client/numpy_client.py", line 227, in _fit
    results = self.numpy_client.fit(parameters, ins.config)  # type: ignore
              ^^^^^^^^^^^^^^^^^^^^^^^^^^^^^^^^^^^^^^^^^^^^^
  File "/content/cluster-CDCSF/fedprox/fedprox/client.py", line 254, in fit
    raise e
  File "/content/cluster-CDCSF/fedprox/fedprox/client.py", line 222, in fit
    self.train(self.net, self.traindata, self.client_id, epochs=self.local_epochs, simulate_delay=simulate_delay)
               ^^^^^^^^
AttributeError: 'FederatedClient' object has no attribute 'net'

The above exception was the direct cause of the following exception:

[36mray::ClientAppActor.run()[39m (pid=39710, ip=172.28.0.12, actor_id=386d1b25a36388b25c53d2e501000000, repr=<flwr.simulation.ray_transport.ray_actor.ClientAppActor object at 0x7ae882f2f770>)
           ^^^^^^^^^^^^^^^^^^^^^^^^^^^^^^^^^^^^
           ^^^^^^^^^^^^^^^^^^^^^^^^^^^^^^^
  File "/usr/local/lib/python3.12/dist-packages/flwr/simulation/ray_transport/ray_actor.py", line 64, in run
    raise ClientAppException(str(ex)) from ex
flwr.client.client_app.ClientAppException: 
Exception ClientAppException occurred. Message: 'FederatedClient' object has no attribute 'net'
[2025-10-04 13:37:45,839][flwr][ERROR] - Traceback (most recent call last):
  File "/usr/local/lib/python3.12/dist-packages/flwr/server/superlink/fleet/vce/vce_api.py", line 111, in worker
    out_mssg, updated_context = backend.process_message(message, context)
                                ^^^^^^^^^^^^^^^^^^^^^^^^^^^^^^^^^^^^^^^^^
  File "/usr/local/lib/python3.12/dist-packages/flwr/server/superlink/fleet/vce/backend/raybackend.py", line 189, in process_message
    raise ex
  File "/usr/local/lib/python3.12/dist-packages/flwr/server/superlink/fleet/vce/backend/raybackend.py", line 176, in process_message
    ) = self.pool.fetch_result_and_return_actor_to_pool(future)
        ^^^^^^^^^^^^^^^^^^^^^^^^^^^^^^^^^^^^^^^^^^^^^^^^^^^^^^^
  File "/usr/local/lib/python3.12/dist-packages/flwr/simulation/ray_transport/ray_actor.py", line 480, in fetch_result_and_return_actor_to_pool
    _, out_mssg, updated_context = ray.get(future)
                                   ^^^^^^^^^^^^^^^
  File "/usr/local/lib/python3.12/dist-packages/ray/_private/auto_init_hook.py", line 21, in auto_init_wrapper
    return fn(*args, **kwargs)
           ^^^^^^^^^^^^^^^^^^^
  File "/usr/local/lib/python3.12/dist-packages/ray/_private/client_mode_hook.py", line 103, in wrapper
    return func(*args, **kwargs)
           ^^^^^^^^^^^^^^^^^^^^^
  File "/usr/local/lib/python3.12/dist-packages/ray/_private/worker.py", line 2639, in get
    values, debugger_breakpoint = worker.get_objects(object_refs, timeout=timeout)
                                  ^^^^^^^^^^^^^^^^^^^^^^^^^^^^^^^^^^^^^^^^^^^^^^^^
  File "/usr/local/lib/python3.12/dist-packages/ray/_private/worker.py", line 864, in get_objects
    raise value.as_instanceof_cause()
ray.exceptions.RayTaskError(ClientAppException): [36mray::ClientAppActor.run()[39m (pid=39710, ip=172.28.0.12, actor_id=386d1b25a36388b25c53d2e501000000, repr=<flwr.simulation.ray_transport.ray_actor.ClientAppActor object at 0x7ae882f2f770>)
                  ^^^^^^^^^^^^^^^^^^^^^^^^^^^^^^^^^^^^^
  File "/usr/local/lib/python3.12/dist-packages/flwr/client/client_app.py", line 144, in __call__
    return self._call(message, context)
           ^^^^^^^^^^^^^^^^^^^^^^^^^^^^
  File "/usr/local/lib/python3.12/dist-packages/flwr/client/client_app.py", line 128, in ffn
    out_message = handle_legacy_message_from_msgtype(
                  ^^^^^^^^^^^^^^^^^^^^^^^^^^^^^^^^^^^
  File "/usr/local/lib/python3.12/dist-packages/flwr/client/message_handler/message_handler.py", line 128, in handle_legacy_message_from_msgtype
    fit_res = maybe_call_fit(
              ^^^^^^^^^^^^^^^
  File "/usr/local/lib/python3.12/dist-packages/flwr/client/client.py", line 224, in maybe_call_fit
    return client.fit(fit_ins)
           ^^^^^^^^^^^^^^^^^^^
  File "/usr/local/lib/python3.12/dist-packages/flwr/client/numpy_client.py", line 227, in _fit
    results = self.numpy_client.fit(parameters, ins.config)  # type: ignore
              ^^^^^^^^^^^^^^^^^^^^^^^^^^^^^^^^^^^^^^^^^^^^^
  File "/content/cluster-CDCSF/fedprox/fedprox/client.py", line 254, in fit
    raise e
  File "/content/cluster-CDCSF/fedprox/fedprox/client.py", line 222, in fit
    self.train(self.net, self.traindata, self.client_id, epochs=self.local_epochs, simulate_delay=simulate_delay)
               ^^^^^^^^
AttributeError: 'FederatedClient' object has no attribute 'net'

The above exception was the direct cause of the following exception:

[36mray::ClientAppActor.run()[39m (pid=39710, ip=172.28.0.12, actor_id=386d1b25a36388b25c53d2e501000000, repr=<flwr.simulation.ray_transport.ray_actor.ClientAppActor object at 0x7ae882f2f770>)
           ^^^^^^^^^^^^^^^^^^^^^^^^^^^^^^^^^^^^
           ^^^^^^^^^^^^^^^^^^^^^^^^^^^^^^^
  File "/usr/local/lib/python3.12/dist-packages/flwr/simulation/ray_transport/ray_actor.py", line 64, in run
    raise ClientAppException(str(ex)) from ex
flwr.client.client_app.ClientAppException: 
Exception ClientAppException occurred. Message: 'FederatedClient' object has no attribute 'net'

[2025-10-04 13:37:46,464][flwr][ERROR] - An exception was raised when processing a message by RayBackend
[2025-10-04 13:37:46,465][flwr][ERROR] - [36mray::ClientAppActor.run()[39m (pid=39710, ip=172.28.0.12, actor_id=386d1b25a36388b25c53d2e501000000, repr=<flwr.simulation.ray_transport.ray_actor.ClientAppActor object at 0x7ae882f2f770>)
                  ^^^^^^^^^^^^^^^^^^^^^^^^^^^^^^^^^^^^^
  File "/usr/local/lib/python3.12/dist-packages/flwr/client/client_app.py", line 144, in __call__
    return self._call(message, context)
           ^^^^^^^^^^^^^^^^^^^^^^^^^^^^
  File "/usr/local/lib/python3.12/dist-packages/flwr/client/client_app.py", line 128, in ffn
    out_message = handle_legacy_message_from_msgtype(
                  ^^^^^^^^^^^^^^^^^^^^^^^^^^^^^^^^^^^
  File "/usr/local/lib/python3.12/dist-packages/flwr/client/message_handler/message_handler.py", line 128, in handle_legacy_message_from_msgtype
    fit_res = maybe_call_fit(
              ^^^^^^^^^^^^^^^
  File "/usr/local/lib/python3.12/dist-packages/flwr/client/client.py", line 224, in maybe_call_fit
    return client.fit(fit_ins)
           ^^^^^^^^^^^^^^^^^^^
  File "/usr/local/lib/python3.12/dist-packages/flwr/client/numpy_client.py", line 227, in _fit
    results = self.numpy_client.fit(parameters, ins.config)  # type: ignore
              ^^^^^^^^^^^^^^^^^^^^^^^^^^^^^^^^^^^^^^^^^^^^^
  File "/content/cluster-CDCSF/fedprox/fedprox/client.py", line 254, in fit
    raise e
  File "/content/cluster-CDCSF/fedprox/fedprox/client.py", line 222, in fit
    self.train(self.net, self.traindata, self.client_id, epochs=self.local_epochs, simulate_delay=simulate_delay)
               ^^^^^^^^
AttributeError: 'FederatedClient' object has no attribute 'net'

The above exception was the direct cause of the following exception:

[36mray::ClientAppActor.run()[39m (pid=39710, ip=172.28.0.12, actor_id=386d1b25a36388b25c53d2e501000000, repr=<flwr.simulation.ray_transport.ray_actor.ClientAppActor object at 0x7ae882f2f770>)
           ^^^^^^^^^^^^^^^^^^^^^^^^^^^^^^^^^^^^
           ^^^^^^^^^^^^^^^^^^^^^^^^^^^^^^^
  File "/usr/local/lib/python3.12/dist-packages/flwr/simulation/ray_transport/ray_actor.py", line 64, in run
    raise ClientAppException(str(ex)) from ex
flwr.client.client_app.ClientAppException: 
Exception ClientAppException occurred. Message: 'FederatedClient' object has no attribute 'net'
[2025-10-04 13:37:46,466][flwr][ERROR] - Traceback (most recent call last):
  File "/usr/local/lib/python3.12/dist-packages/flwr/server/superlink/fleet/vce/vce_api.py", line 111, in worker
    out_mssg, updated_context = backend.process_message(message, context)
                                ^^^^^^^^^^^^^^^^^^^^^^^^^^^^^^^^^^^^^^^^^
  File "/usr/local/lib/python3.12/dist-packages/flwr/server/superlink/fleet/vce/backend/raybackend.py", line 189, in process_message
    raise ex
  File "/usr/local/lib/python3.12/dist-packages/flwr/server/superlink/fleet/vce/backend/raybackend.py", line 176, in process_message
    ) = self.pool.fetch_result_and_return_actor_to_pool(future)
        ^^^^^^^^^^^^^^^^^^^^^^^^^^^^^^^^^^^^^^^^^^^^^^^^^^^^^^^
  File "/usr/local/lib/python3.12/dist-packages/flwr/simulation/ray_transport/ray_actor.py", line 480, in fetch_result_and_return_actor_to_pool
    _, out_mssg, updated_context = ray.get(future)
                                   ^^^^^^^^^^^^^^^
  File "/usr/local/lib/python3.12/dist-packages/ray/_private/auto_init_hook.py", line 21, in auto_init_wrapper
    return fn(*args, **kwargs)
           ^^^^^^^^^^^^^^^^^^^
  File "/usr/local/lib/python3.12/dist-packages/ray/_private/client_mode_hook.py", line 103, in wrapper
    return func(*args, **kwargs)
           ^^^^^^^^^^^^^^^^^^^^^
  File "/usr/local/lib/python3.12/dist-packages/ray/_private/worker.py", line 2639, in get
    values, debugger_breakpoint = worker.get_objects(object_refs, timeout=timeout)
                                  ^^^^^^^^^^^^^^^^^^^^^^^^^^^^^^^^^^^^^^^^^^^^^^^^
  File "/usr/local/lib/python3.12/dist-packages/ray/_private/worker.py", line 864, in get_objects
    raise value.as_instanceof_cause()
ray.exceptions.RayTaskError(ClientAppException): [36mray::ClientAppActor.run()[39m (pid=39710, ip=172.28.0.12, actor_id=386d1b25a36388b25c53d2e501000000, repr=<flwr.simulation.ray_transport.ray_actor.ClientAppActor object at 0x7ae882f2f770>)
                  ^^^^^^^^^^^^^^^^^^^^^^^^^^^^^^^^^^^^^
  File "/usr/local/lib/python3.12/dist-packages/flwr/client/client_app.py", line 144, in __call__
    return self._call(message, context)
           ^^^^^^^^^^^^^^^^^^^^^^^^^^^^
  File "/usr/local/lib/python3.12/dist-packages/flwr/client/client_app.py", line 128, in ffn
    out_message = handle_legacy_message_from_msgtype(
                  ^^^^^^^^^^^^^^^^^^^^^^^^^^^^^^^^^^^
  File "/usr/local/lib/python3.12/dist-packages/flwr/client/message_handler/message_handler.py", line 128, in handle_legacy_message_from_msgtype
    fit_res = maybe_call_fit(
              ^^^^^^^^^^^^^^^
  File "/usr/local/lib/python3.12/dist-packages/flwr/client/client.py", line 224, in maybe_call_fit
    return client.fit(fit_ins)
           ^^^^^^^^^^^^^^^^^^^
  File "/usr/local/lib/python3.12/dist-packages/flwr/client/numpy_client.py", line 227, in _fit
    results = self.numpy_client.fit(parameters, ins.config)  # type: ignore
              ^^^^^^^^^^^^^^^^^^^^^^^^^^^^^^^^^^^^^^^^^^^^^
  File "/content/cluster-CDCSF/fedprox/fedprox/client.py", line 254, in fit
    raise e
  File "/content/cluster-CDCSF/fedprox/fedprox/client.py", line 222, in fit
    self.train(self.net, self.traindata, self.client_id, epochs=self.local_epochs, simulate_delay=simulate_delay)
               ^^^^^^^^
AttributeError: 'FederatedClient' object has no attribute 'net'

The above exception was the direct cause of the following exception:

[36mray::ClientAppActor.run()[39m (pid=39710, ip=172.28.0.12, actor_id=386d1b25a36388b25c53d2e501000000, repr=<flwr.simulation.ray_transport.ray_actor.ClientAppActor object at 0x7ae882f2f770>)
           ^^^^^^^^^^^^^^^^^^^^^^^^^^^^^^^^^^^^
           ^^^^^^^^^^^^^^^^^^^^^^^^^^^^^^^
  File "/usr/local/lib/python3.12/dist-packages/flwr/simulation/ray_transport/ray_actor.py", line 64, in run
    raise ClientAppException(str(ex)) from ex
flwr.client.client_app.ClientAppException: 
Exception ClientAppException occurred. Message: 'FederatedClient' object has no attribute 'net'

[2025-10-04 13:37:47,156][flwr][ERROR] - An exception was raised when processing a message by RayBackend
[2025-10-04 13:37:47,156][flwr][ERROR] - [36mray::ClientAppActor.run()[39m (pid=39710, ip=172.28.0.12, actor_id=386d1b25a36388b25c53d2e501000000, repr=<flwr.simulation.ray_transport.ray_actor.ClientAppActor object at 0x7ae882f2f770>)
                  ^^^^^^^^^^^^^^^^^^^^^^^^^^^^^^^^^^^^^
  File "/usr/local/lib/python3.12/dist-packages/flwr/client/client_app.py", line 144, in __call__
    return self._call(message, context)
           ^^^^^^^^^^^^^^^^^^^^^^^^^^^^
  File "/usr/local/lib/python3.12/dist-packages/flwr/client/client_app.py", line 128, in ffn
    out_message = handle_legacy_message_from_msgtype(
                  ^^^^^^^^^^^^^^^^^^^^^^^^^^^^^^^^^^^
  File "/usr/local/lib/python3.12/dist-packages/flwr/client/message_handler/message_handler.py", line 128, in handle_legacy_message_from_msgtype
    fit_res = maybe_call_fit(
              ^^^^^^^^^^^^^^^
  File "/usr/local/lib/python3.12/dist-packages/flwr/client/client.py", line 224, in maybe_call_fit
    return client.fit(fit_ins)
           ^^^^^^^^^^^^^^^^^^^
  File "/usr/local/lib/python3.12/dist-packages/flwr/client/numpy_client.py", line 227, in _fit
    results = self.numpy_client.fit(parameters, ins.config)  # type: ignore
              ^^^^^^^^^^^^^^^^^^^^^^^^^^^^^^^^^^^^^^^^^^^^^
  File "/content/cluster-CDCSF/fedprox/fedprox/client.py", line 254, in fit
    raise e
  File "/content/cluster-CDCSF/fedprox/fedprox/client.py", line 222, in fit
    self.train(self.net, self.traindata, self.client_id, epochs=self.local_epochs, simulate_delay=simulate_delay)
               ^^^^^^^^
AttributeError: 'FederatedClient' object has no attribute 'net'

The above exception was the direct cause of the following exception:

[36mray::ClientAppActor.run()[39m (pid=39710, ip=172.28.0.12, actor_id=386d1b25a36388b25c53d2e501000000, repr=<flwr.simulation.ray_transport.ray_actor.ClientAppActor object at 0x7ae882f2f770>)
           ^^^^^^^^^^^^^^^^^^^^^^^^^^^^^^^^^^^^
           ^^^^^^^^^^^^^^^^^^^^^^^^^^^^^^^
  File "/usr/local/lib/python3.12/dist-packages/flwr/simulation/ray_transport/ray_actor.py", line 64, in run
    raise ClientAppException(str(ex)) from ex
flwr.client.client_app.ClientAppException: 
Exception ClientAppException occurred. Message: 'FederatedClient' object has no attribute 'net'
[2025-10-04 13:37:47,157][flwr][ERROR] - Traceback (most recent call last):
  File "/usr/local/lib/python3.12/dist-packages/flwr/server/superlink/fleet/vce/vce_api.py", line 111, in worker
    out_mssg, updated_context = backend.process_message(message, context)
                                ^^^^^^^^^^^^^^^^^^^^^^^^^^^^^^^^^^^^^^^^^
  File "/usr/local/lib/python3.12/dist-packages/flwr/server/superlink/fleet/vce/backend/raybackend.py", line 189, in process_message
    raise ex
  File "/usr/local/lib/python3.12/dist-packages/flwr/server/superlink/fleet/vce/backend/raybackend.py", line 176, in process_message
    ) = self.pool.fetch_result_and_return_actor_to_pool(future)
        ^^^^^^^^^^^^^^^^^^^^^^^^^^^^^^^^^^^^^^^^^^^^^^^^^^^^^^^
  File "/usr/local/lib/python3.12/dist-packages/flwr/simulation/ray_transport/ray_actor.py", line 480, in fetch_result_and_return_actor_to_pool
    _, out_mssg, updated_context = ray.get(future)
                                   ^^^^^^^^^^^^^^^
  File "/usr/local/lib/python3.12/dist-packages/ray/_private/auto_init_hook.py", line 21, in auto_init_wrapper
    return fn(*args, **kwargs)
           ^^^^^^^^^^^^^^^^^^^
  File "/usr/local/lib/python3.12/dist-packages/ray/_private/client_mode_hook.py", line 103, in wrapper
    return func(*args, **kwargs)
           ^^^^^^^^^^^^^^^^^^^^^
  File "/usr/local/lib/python3.12/dist-packages/ray/_private/worker.py", line 2639, in get
    values, debugger_breakpoint = worker.get_objects(object_refs, timeout=timeout)
                                  ^^^^^^^^^^^^^^^^^^^^^^^^^^^^^^^^^^^^^^^^^^^^^^^^
  File "/usr/local/lib/python3.12/dist-packages/ray/_private/worker.py", line 864, in get_objects
    raise value.as_instanceof_cause()
ray.exceptions.RayTaskError(ClientAppException): [36mray::ClientAppActor.run()[39m (pid=39710, ip=172.28.0.12, actor_id=386d1b25a36388b25c53d2e501000000, repr=<flwr.simulation.ray_transport.ray_actor.ClientAppActor object at 0x7ae882f2f770>)
                  ^^^^^^^^^^^^^^^^^^^^^^^^^^^^^^^^^^^^^
  File "/usr/local/lib/python3.12/dist-packages/flwr/client/client_app.py", line 144, in __call__
    return self._call(message, context)
           ^^^^^^^^^^^^^^^^^^^^^^^^^^^^
  File "/usr/local/lib/python3.12/dist-packages/flwr/client/client_app.py", line 128, in ffn
    out_message = handle_legacy_message_from_msgtype(
                  ^^^^^^^^^^^^^^^^^^^^^^^^^^^^^^^^^^^
  File "/usr/local/lib/python3.12/dist-packages/flwr/client/message_handler/message_handler.py", line 128, in handle_legacy_message_from_msgtype
    fit_res = maybe_call_fit(
              ^^^^^^^^^^^^^^^
  File "/usr/local/lib/python3.12/dist-packages/flwr/client/client.py", line 224, in maybe_call_fit
    return client.fit(fit_ins)
           ^^^^^^^^^^^^^^^^^^^
  File "/usr/local/lib/python3.12/dist-packages/flwr/client/numpy_client.py", line 227, in _fit
    results = self.numpy_client.fit(parameters, ins.config)  # type: ignore
              ^^^^^^^^^^^^^^^^^^^^^^^^^^^^^^^^^^^^^^^^^^^^^
  File "/content/cluster-CDCSF/fedprox/fedprox/client.py", line 254, in fit
    raise e
  File "/content/cluster-CDCSF/fedprox/fedprox/client.py", line 222, in fit
    self.train(self.net, self.traindata, self.client_id, epochs=self.local_epochs, simulate_delay=simulate_delay)
               ^^^^^^^^
AttributeError: 'FederatedClient' object has no attribute 'net'

The above exception was the direct cause of the following exception:

[36mray::ClientAppActor.run()[39m (pid=39710, ip=172.28.0.12, actor_id=386d1b25a36388b25c53d2e501000000, repr=<flwr.simulation.ray_transport.ray_actor.ClientAppActor object at 0x7ae882f2f770>)
           ^^^^^^^^^^^^^^^^^^^^^^^^^^^^^^^^^^^^
           ^^^^^^^^^^^^^^^^^^^^^^^^^^^^^^^
  File "/usr/local/lib/python3.12/dist-packages/flwr/simulation/ray_transport/ray_actor.py", line 64, in run
    raise ClientAppException(str(ex)) from ex
flwr.client.client_app.ClientAppException: 
Exception ClientAppException occurred. Message: 'FederatedClient' object has no attribute 'net'

[2025-10-04 13:37:47,162][flwr][INFO] - aggregate_fit: received 0 results and 3 failures
[2025-10-04 13:37:47,222][flwr][INFO] - configure_evaluate: strategy sampled 3 clients (out of 3)
[2025-10-04 13:38:12,233][flwr][INFO] - aggregate_evaluate: received 3 results and 0 failures
[2025-10-04 13:38:12,286][flwr][INFO] - 
[2025-10-04 13:38:12,286][flwr][INFO] - [ROUND 3]
[2025-10-04 13:38:12,287][flwr][INFO] - configure_fit: strategy sampled 3 clients (out of 3)
[2025-10-04 13:38:12,972][flwr][ERROR] - An exception was raised when processing a message by RayBackend
[2025-10-04 13:38:12,972][flwr][ERROR] - [36mray::ClientAppActor.run()[39m (pid=39710, ip=172.28.0.12, actor_id=386d1b25a36388b25c53d2e501000000, repr=<flwr.simulation.ray_transport.ray_actor.ClientAppActor object at 0x7ae882f2f770>)
                  ^^^^^^^^^^^^^^^^^^^^^^^^^^^^^^^^^^^^^
  File "/usr/local/lib/python3.12/dist-packages/flwr/client/client_app.py", line 144, in __call__
    return self._call(message, context)
           ^^^^^^^^^^^^^^^^^^^^^^^^^^^^
  File "/usr/local/lib/python3.12/dist-packages/flwr/client/client_app.py", line 128, in ffn
    out_message = handle_legacy_message_from_msgtype(
                  ^^^^^^^^^^^^^^^^^^^^^^^^^^^^^^^^^^^
  File "/usr/local/lib/python3.12/dist-packages/flwr/client/message_handler/message_handler.py", line 128, in handle_legacy_message_from_msgtype
    fit_res = maybe_call_fit(
              ^^^^^^^^^^^^^^^
  File "/usr/local/lib/python3.12/dist-packages/flwr/client/client.py", line 224, in maybe_call_fit
    return client.fit(fit_ins)
           ^^^^^^^^^^^^^^^^^^^
  File "/usr/local/lib/python3.12/dist-packages/flwr/client/numpy_client.py", line 227, in _fit
    results = self.numpy_client.fit(parameters, ins.config)  # type: ignore
              ^^^^^^^^^^^^^^^^^^^^^^^^^^^^^^^^^^^^^^^^^^^^^
  File "/content/cluster-CDCSF/fedprox/fedprox/client.py", line 254, in fit
    raise e
  File "/content/cluster-CDCSF/fedprox/fedprox/client.py", line 222, in fit
    self.train(self.net, self.traindata, self.client_id, epochs=self.local_epochs, simulate_delay=simulate_delay)
               ^^^^^^^^
AttributeError: 'FederatedClient' object has no attribute 'net'

The above exception was the direct cause of the following exception:

[36mray::ClientAppActor.run()[39m (pid=39710, ip=172.28.0.12, actor_id=386d1b25a36388b25c53d2e501000000, repr=<flwr.simulation.ray_transport.ray_actor.ClientAppActor object at 0x7ae882f2f770>)
           ^^^^^^^^^^^^^^^^^^^^^^^^^^^^^^^^^^^^
           ^^^^^^^^^^^^^^^^^^^^^^^^^^^^^^^
  File "/usr/local/lib/python3.12/dist-packages/flwr/simulation/ray_transport/ray_actor.py", line 64, in run
    raise ClientAppException(str(ex)) from ex
flwr.client.client_app.ClientAppException: 
Exception ClientAppException occurred. Message: 'FederatedClient' object has no attribute 'net'
[2025-10-04 13:38:12,974][flwr][ERROR] - Traceback (most recent call last):
  File "/usr/local/lib/python3.12/dist-packages/flwr/server/superlink/fleet/vce/vce_api.py", line 111, in worker
    out_mssg, updated_context = backend.process_message(message, context)
                                ^^^^^^^^^^^^^^^^^^^^^^^^^^^^^^^^^^^^^^^^^
  File "/usr/local/lib/python3.12/dist-packages/flwr/server/superlink/fleet/vce/backend/raybackend.py", line 189, in process_message
    raise ex
  File "/usr/local/lib/python3.12/dist-packages/flwr/server/superlink/fleet/vce/backend/raybackend.py", line 176, in process_message
    ) = self.pool.fetch_result_and_return_actor_to_pool(future)
        ^^^^^^^^^^^^^^^^^^^^^^^^^^^^^^^^^^^^^^^^^^^^^^^^^^^^^^^
  File "/usr/local/lib/python3.12/dist-packages/flwr/simulation/ray_transport/ray_actor.py", line 480, in fetch_result_and_return_actor_to_pool
    _, out_mssg, updated_context = ray.get(future)
                                   ^^^^^^^^^^^^^^^
  File "/usr/local/lib/python3.12/dist-packages/ray/_private/auto_init_hook.py", line 21, in auto_init_wrapper
    return fn(*args, **kwargs)
           ^^^^^^^^^^^^^^^^^^^
  File "/usr/local/lib/python3.12/dist-packages/ray/_private/client_mode_hook.py", line 103, in wrapper
    return func(*args, **kwargs)
           ^^^^^^^^^^^^^^^^^^^^^
  File "/usr/local/lib/python3.12/dist-packages/ray/_private/worker.py", line 2639, in get
    values, debugger_breakpoint = worker.get_objects(object_refs, timeout=timeout)
                                  ^^^^^^^^^^^^^^^^^^^^^^^^^^^^^^^^^^^^^^^^^^^^^^^^
  File "/usr/local/lib/python3.12/dist-packages/ray/_private/worker.py", line 864, in get_objects
    raise value.as_instanceof_cause()
ray.exceptions.RayTaskError(ClientAppException): [36mray::ClientAppActor.run()[39m (pid=39710, ip=172.28.0.12, actor_id=386d1b25a36388b25c53d2e501000000, repr=<flwr.simulation.ray_transport.ray_actor.ClientAppActor object at 0x7ae882f2f770>)
                  ^^^^^^^^^^^^^^^^^^^^^^^^^^^^^^^^^^^^^
  File "/usr/local/lib/python3.12/dist-packages/flwr/client/client_app.py", line 144, in __call__
    return self._call(message, context)
           ^^^^^^^^^^^^^^^^^^^^^^^^^^^^
  File "/usr/local/lib/python3.12/dist-packages/flwr/client/client_app.py", line 128, in ffn
    out_message = handle_legacy_message_from_msgtype(
                  ^^^^^^^^^^^^^^^^^^^^^^^^^^^^^^^^^^^
  File "/usr/local/lib/python3.12/dist-packages/flwr/client/message_handler/message_handler.py", line 128, in handle_legacy_message_from_msgtype
    fit_res = maybe_call_fit(
              ^^^^^^^^^^^^^^^
  File "/usr/local/lib/python3.12/dist-packages/flwr/client/client.py", line 224, in maybe_call_fit
    return client.fit(fit_ins)
           ^^^^^^^^^^^^^^^^^^^
  File "/usr/local/lib/python3.12/dist-packages/flwr/client/numpy_client.py", line 227, in _fit
    results = self.numpy_client.fit(parameters, ins.config)  # type: ignore
              ^^^^^^^^^^^^^^^^^^^^^^^^^^^^^^^^^^^^^^^^^^^^^
  File "/content/cluster-CDCSF/fedprox/fedprox/client.py", line 254, in fit
    raise e
  File "/content/cluster-CDCSF/fedprox/fedprox/client.py", line 222, in fit
    self.train(self.net, self.traindata, self.client_id, epochs=self.local_epochs, simulate_delay=simulate_delay)
               ^^^^^^^^
AttributeError: 'FederatedClient' object has no attribute 'net'

The above exception was the direct cause of the following exception:

[36mray::ClientAppActor.run()[39m (pid=39710, ip=172.28.0.12, actor_id=386d1b25a36388b25c53d2e501000000, repr=<flwr.simulation.ray_transport.ray_actor.ClientAppActor object at 0x7ae882f2f770>)
           ^^^^^^^^^^^^^^^^^^^^^^^^^^^^^^^^^^^^
           ^^^^^^^^^^^^^^^^^^^^^^^^^^^^^^^
  File "/usr/local/lib/python3.12/dist-packages/flwr/simulation/ray_transport/ray_actor.py", line 64, in run
    raise ClientAppException(str(ex)) from ex
flwr.client.client_app.ClientAppException: 
Exception ClientAppException occurred. Message: 'FederatedClient' object has no attribute 'net'

[2025-10-04 13:38:13,628][flwr][ERROR] - An exception was raised when processing a message by RayBackend
[2025-10-04 13:38:13,629][flwr][ERROR] - [36mray::ClientAppActor.run()[39m (pid=39710, ip=172.28.0.12, actor_id=386d1b25a36388b25c53d2e501000000, repr=<flwr.simulation.ray_transport.ray_actor.ClientAppActor object at 0x7ae882f2f770>)
                  ^^^^^^^^^^^^^^^^^^^^^^^^^^^^^^^^^^^^^
  File "/usr/local/lib/python3.12/dist-packages/flwr/client/client_app.py", line 144, in __call__
    return self._call(message, context)
           ^^^^^^^^^^^^^^^^^^^^^^^^^^^^
  File "/usr/local/lib/python3.12/dist-packages/flwr/client/client_app.py", line 128, in ffn
    out_message = handle_legacy_message_from_msgtype(
                  ^^^^^^^^^^^^^^^^^^^^^^^^^^^^^^^^^^^
  File "/usr/local/lib/python3.12/dist-packages/flwr/client/message_handler/message_handler.py", line 128, in handle_legacy_message_from_msgtype
    fit_res = maybe_call_fit(
              ^^^^^^^^^^^^^^^
  File "/usr/local/lib/python3.12/dist-packages/flwr/client/client.py", line 224, in maybe_call_fit
    return client.fit(fit_ins)
           ^^^^^^^^^^^^^^^^^^^
  File "/usr/local/lib/python3.12/dist-packages/flwr/client/numpy_client.py", line 227, in _fit
    results = self.numpy_client.fit(parameters, ins.config)  # type: ignore
              ^^^^^^^^^^^^^^^^^^^^^^^^^^^^^^^^^^^^^^^^^^^^^
  File "/content/cluster-CDCSF/fedprox/fedprox/client.py", line 254, in fit
    raise e
  File "/content/cluster-CDCSF/fedprox/fedprox/client.py", line 222, in fit
    self.train(self.net, self.traindata, self.client_id, epochs=self.local_epochs, simulate_delay=simulate_delay)
               ^^^^^^^^
AttributeError: 'FederatedClient' object has no attribute 'net'

The above exception was the direct cause of the following exception:

[36mray::ClientAppActor.run()[39m (pid=39710, ip=172.28.0.12, actor_id=386d1b25a36388b25c53d2e501000000, repr=<flwr.simulation.ray_transport.ray_actor.ClientAppActor object at 0x7ae882f2f770>)
           ^^^^^^^^^^^^^^^^^^^^^^^^^^^^^^^^^^^^
           ^^^^^^^^^^^^^^^^^^^^^^^^^^^^^^^
  File "/usr/local/lib/python3.12/dist-packages/flwr/simulation/ray_transport/ray_actor.py", line 64, in run
    raise ClientAppException(str(ex)) from ex
flwr.client.client_app.ClientAppException: 
Exception ClientAppException occurred. Message: 'FederatedClient' object has no attribute 'net'
[2025-10-04 13:38:13,630][flwr][ERROR] - Traceback (most recent call last):
  File "/usr/local/lib/python3.12/dist-packages/flwr/server/superlink/fleet/vce/vce_api.py", line 111, in worker
    out_mssg, updated_context = backend.process_message(message, context)
                                ^^^^^^^^^^^^^^^^^^^^^^^^^^^^^^^^^^^^^^^^^
  File "/usr/local/lib/python3.12/dist-packages/flwr/server/superlink/fleet/vce/backend/raybackend.py", line 189, in process_message
    raise ex
  File "/usr/local/lib/python3.12/dist-packages/flwr/server/superlink/fleet/vce/backend/raybackend.py", line 176, in process_message
    ) = self.pool.fetch_result_and_return_actor_to_pool(future)
        ^^^^^^^^^^^^^^^^^^^^^^^^^^^^^^^^^^^^^^^^^^^^^^^^^^^^^^^
  File "/usr/local/lib/python3.12/dist-packages/flwr/simulation/ray_transport/ray_actor.py", line 480, in fetch_result_and_return_actor_to_pool
    _, out_mssg, updated_context = ray.get(future)
                                   ^^^^^^^^^^^^^^^
  File "/usr/local/lib/python3.12/dist-packages/ray/_private/auto_init_hook.py", line 21, in auto_init_wrapper
    return fn(*args, **kwargs)
           ^^^^^^^^^^^^^^^^^^^
  File "/usr/local/lib/python3.12/dist-packages/ray/_private/client_mode_hook.py", line 103, in wrapper
    return func(*args, **kwargs)
           ^^^^^^^^^^^^^^^^^^^^^
  File "/usr/local/lib/python3.12/dist-packages/ray/_private/worker.py", line 2639, in get
    values, debugger_breakpoint = worker.get_objects(object_refs, timeout=timeout)
                                  ^^^^^^^^^^^^^^^^^^^^^^^^^^^^^^^^^^^^^^^^^^^^^^^^
  File "/usr/local/lib/python3.12/dist-packages/ray/_private/worker.py", line 864, in get_objects
    raise value.as_instanceof_cause()
ray.exceptions.RayTaskError(ClientAppException): [36mray::ClientAppActor.run()[39m (pid=39710, ip=172.28.0.12, actor_id=386d1b25a36388b25c53d2e501000000, repr=<flwr.simulation.ray_transport.ray_actor.ClientAppActor object at 0x7ae882f2f770>)
                  ^^^^^^^^^^^^^^^^^^^^^^^^^^^^^^^^^^^^^
  File "/usr/local/lib/python3.12/dist-packages/flwr/client/client_app.py", line 144, in __call__
    return self._call(message, context)
           ^^^^^^^^^^^^^^^^^^^^^^^^^^^^
  File "/usr/local/lib/python3.12/dist-packages/flwr/client/client_app.py", line 128, in ffn
    out_message = handle_legacy_message_from_msgtype(
                  ^^^^^^^^^^^^^^^^^^^^^^^^^^^^^^^^^^^
  File "/usr/local/lib/python3.12/dist-packages/flwr/client/message_handler/message_handler.py", line 128, in handle_legacy_message_from_msgtype
    fit_res = maybe_call_fit(
              ^^^^^^^^^^^^^^^
  File "/usr/local/lib/python3.12/dist-packages/flwr/client/client.py", line 224, in maybe_call_fit
    return client.fit(fit_ins)
           ^^^^^^^^^^^^^^^^^^^
  File "/usr/local/lib/python3.12/dist-packages/flwr/client/numpy_client.py", line 227, in _fit
    results = self.numpy_client.fit(parameters, ins.config)  # type: ignore
              ^^^^^^^^^^^^^^^^^^^^^^^^^^^^^^^^^^^^^^^^^^^^^
  File "/content/cluster-CDCSF/fedprox/fedprox/client.py", line 254, in fit
    raise e
  File "/content/cluster-CDCSF/fedprox/fedprox/client.py", line 222, in fit
    self.train(self.net, self.traindata, self.client_id, epochs=self.local_epochs, simulate_delay=simulate_delay)
               ^^^^^^^^
AttributeError: 'FederatedClient' object has no attribute 'net'

The above exception was the direct cause of the following exception:

[36mray::ClientAppActor.run()[39m (pid=39710, ip=172.28.0.12, actor_id=386d1b25a36388b25c53d2e501000000, repr=<flwr.simulation.ray_transport.ray_actor.ClientAppActor object at 0x7ae882f2f770>)
           ^^^^^^^^^^^^^^^^^^^^^^^^^^^^^^^^^^^^
           ^^^^^^^^^^^^^^^^^^^^^^^^^^^^^^^
  File "/usr/local/lib/python3.12/dist-packages/flwr/simulation/ray_transport/ray_actor.py", line 64, in run
    raise ClientAppException(str(ex)) from ex
flwr.client.client_app.ClientAppException: 
Exception ClientAppException occurred. Message: 'FederatedClient' object has no attribute 'net'

[2025-10-04 13:38:14,283][flwr][ERROR] - An exception was raised when processing a message by RayBackend
[2025-10-04 13:38:14,284][flwr][ERROR] - [36mray::ClientAppActor.run()[39m (pid=39710, ip=172.28.0.12, actor_id=386d1b25a36388b25c53d2e501000000, repr=<flwr.simulation.ray_transport.ray_actor.ClientAppActor object at 0x7ae882f2f770>)
                  ^^^^^^^^^^^^^^^^^^^^^^^^^^^^^^^^^^^^^
  File "/usr/local/lib/python3.12/dist-packages/flwr/client/client_app.py", line 144, in __call__
    return self._call(message, context)
           ^^^^^^^^^^^^^^^^^^^^^^^^^^^^
  File "/usr/local/lib/python3.12/dist-packages/flwr/client/client_app.py", line 128, in ffn
    out_message = handle_legacy_message_from_msgtype(
                  ^^^^^^^^^^^^^^^^^^^^^^^^^^^^^^^^^^^
  File "/usr/local/lib/python3.12/dist-packages/flwr/client/message_handler/message_handler.py", line 128, in handle_legacy_message_from_msgtype
    fit_res = maybe_call_fit(
              ^^^^^^^^^^^^^^^
  File "/usr/local/lib/python3.12/dist-packages/flwr/client/client.py", line 224, in maybe_call_fit
    return client.fit(fit_ins)
           ^^^^^^^^^^^^^^^^^^^
  File "/usr/local/lib/python3.12/dist-packages/flwr/client/numpy_client.py", line 227, in _fit
    results = self.numpy_client.fit(parameters, ins.config)  # type: ignore
              ^^^^^^^^^^^^^^^^^^^^^^^^^^^^^^^^^^^^^^^^^^^^^
  File "/content/cluster-CDCSF/fedprox/fedprox/client.py", line 254, in fit
    raise e
  File "/content/cluster-CDCSF/fedprox/fedprox/client.py", line 222, in fit
    self.train(self.net, self.traindata, self.client_id, epochs=self.local_epochs, simulate_delay=simulate_delay)
               ^^^^^^^^
AttributeError: 'FederatedClient' object has no attribute 'net'

The above exception was the direct cause of the following exception:

[36mray::ClientAppActor.run()[39m (pid=39710, ip=172.28.0.12, actor_id=386d1b25a36388b25c53d2e501000000, repr=<flwr.simulation.ray_transport.ray_actor.ClientAppActor object at 0x7ae882f2f770>)
           ^^^^^^^^^^^^^^^^^^^^^^^^^^^^^^^^^^^^
           ^^^^^^^^^^^^^^^^^^^^^^^^^^^^^^^
  File "/usr/local/lib/python3.12/dist-packages/flwr/simulation/ray_transport/ray_actor.py", line 64, in run
    raise ClientAppException(str(ex)) from ex
flwr.client.client_app.ClientAppException: 
Exception ClientAppException occurred. Message: 'FederatedClient' object has no attribute 'net'
[2025-10-04 13:38:14,284][flwr][ERROR] - Traceback (most recent call last):
  File "/usr/local/lib/python3.12/dist-packages/flwr/server/superlink/fleet/vce/vce_api.py", line 111, in worker
    out_mssg, updated_context = backend.process_message(message, context)
                                ^^^^^^^^^^^^^^^^^^^^^^^^^^^^^^^^^^^^^^^^^
  File "/usr/local/lib/python3.12/dist-packages/flwr/server/superlink/fleet/vce/backend/raybackend.py", line 189, in process_message
    raise ex
  File "/usr/local/lib/python3.12/dist-packages/flwr/server/superlink/fleet/vce/backend/raybackend.py", line 176, in process_message
    ) = self.pool.fetch_result_and_return_actor_to_pool(future)
        ^^^^^^^^^^^^^^^^^^^^^^^^^^^^^^^^^^^^^^^^^^^^^^^^^^^^^^^
  File "/usr/local/lib/python3.12/dist-packages/flwr/simulation/ray_transport/ray_actor.py", line 480, in fetch_result_and_return_actor_to_pool
    _, out_mssg, updated_context = ray.get(future)
                                   ^^^^^^^^^^^^^^^
  File "/usr/local/lib/python3.12/dist-packages/ray/_private/auto_init_hook.py", line 21, in auto_init_wrapper
    return fn(*args, **kwargs)
           ^^^^^^^^^^^^^^^^^^^
  File "/usr/local/lib/python3.12/dist-packages/ray/_private/client_mode_hook.py", line 103, in wrapper
    return func(*args, **kwargs)
           ^^^^^^^^^^^^^^^^^^^^^
  File "/usr/local/lib/python3.12/dist-packages/ray/_private/worker.py", line 2639, in get
    values, debugger_breakpoint = worker.get_objects(object_refs, timeout=timeout)
                                  ^^^^^^^^^^^^^^^^^^^^^^^^^^^^^^^^^^^^^^^^^^^^^^^^
  File "/usr/local/lib/python3.12/dist-packages/ray/_private/worker.py", line 864, in get_objects
    raise value.as_instanceof_cause()
ray.exceptions.RayTaskError(ClientAppException): [36mray::ClientAppActor.run()[39m (pid=39710, ip=172.28.0.12, actor_id=386d1b25a36388b25c53d2e501000000, repr=<flwr.simulation.ray_transport.ray_actor.ClientAppActor object at 0x7ae882f2f770>)
                  ^^^^^^^^^^^^^^^^^^^^^^^^^^^^^^^^^^^^^
  File "/usr/local/lib/python3.12/dist-packages/flwr/client/client_app.py", line 144, in __call__
    return self._call(message, context)
           ^^^^^^^^^^^^^^^^^^^^^^^^^^^^
  File "/usr/local/lib/python3.12/dist-packages/flwr/client/client_app.py", line 128, in ffn
    out_message = handle_legacy_message_from_msgtype(
                  ^^^^^^^^^^^^^^^^^^^^^^^^^^^^^^^^^^^
  File "/usr/local/lib/python3.12/dist-packages/flwr/client/message_handler/message_handler.py", line 128, in handle_legacy_message_from_msgtype
    fit_res = maybe_call_fit(
              ^^^^^^^^^^^^^^^
  File "/usr/local/lib/python3.12/dist-packages/flwr/client/client.py", line 224, in maybe_call_fit
    return client.fit(fit_ins)
           ^^^^^^^^^^^^^^^^^^^
  File "/usr/local/lib/python3.12/dist-packages/flwr/client/numpy_client.py", line 227, in _fit
    results = self.numpy_client.fit(parameters, ins.config)  # type: ignore
              ^^^^^^^^^^^^^^^^^^^^^^^^^^^^^^^^^^^^^^^^^^^^^
  File "/content/cluster-CDCSF/fedprox/fedprox/client.py", line 254, in fit
    raise e
  File "/content/cluster-CDCSF/fedprox/fedprox/client.py", line 222, in fit
    self.train(self.net, self.traindata, self.client_id, epochs=self.local_epochs, simulate_delay=simulate_delay)
               ^^^^^^^^
AttributeError: 'FederatedClient' object has no attribute 'net'

The above exception was the direct cause of the following exception:

[36mray::ClientAppActor.run()[39m (pid=39710, ip=172.28.0.12, actor_id=386d1b25a36388b25c53d2e501000000, repr=<flwr.simulation.ray_transport.ray_actor.ClientAppActor object at 0x7ae882f2f770>)
           ^^^^^^^^^^^^^^^^^^^^^^^^^^^^^^^^^^^^
           ^^^^^^^^^^^^^^^^^^^^^^^^^^^^^^^
  File "/usr/local/lib/python3.12/dist-packages/flwr/simulation/ray_transport/ray_actor.py", line 64, in run
    raise ClientAppException(str(ex)) from ex
flwr.client.client_app.ClientAppException: 
Exception ClientAppException occurred. Message: 'FederatedClient' object has no attribute 'net'

[2025-10-04 13:38:14,313][flwr][INFO] - aggregate_fit: received 0 results and 3 failures
[2025-10-04 13:38:14,370][flwr][INFO] - configure_evaluate: strategy sampled 3 clients (out of 3)
[2025-10-04 13:38:39,475][flwr][INFO] - aggregate_evaluate: received 3 results and 0 failures
[2025-10-04 13:38:39,543][flwr][INFO] - 
[2025-10-04 13:38:39,543][flwr][INFO] - [SUMMARY]
[2025-10-04 13:38:39,543][flwr][INFO] - Run finished 3 round(s) in 82.78s
[2025-10-04 13:38:39,544][flwr][INFO] - 
[2025-10-04 13:38:39,545][flwr][DEBUG] - ServerApp finished running.
[2025-10-04 13:38:39,545][flwr][DEBUG] - ServerApp finished running.
[2025-10-04 13:38:39,545][flwr][DEBUG] - Triggered stop event for Simulation Engine.
[2025-10-04 13:38:40,417][flwr][DEBUG] - Terminated 1 actors
[2025-10-04 13:38:42,157][flwr][DEBUG] - Terminated RayBackend
[2025-10-04 13:38:42,157][flwr][DEBUG] - Stopping Simulation Engine now.
